Workbook
Name TimeSeries: 'SSI cola for the year'!$B$3

Sheet Portfolio Drawdown
A2: Combined liquid portfolio @62 | B2: 1000000
A3: Rate of Return (from Main) | B3: =Main!B14 -> 0.04
A4: Desired Annual spending based at 62 | B4: 100000
A5: CPI | B5: =Main!E12 -> 0.03263964
A10: Age | B10: Year | C10: Desired Annual Spending | D10: Social Security at 62 | E10: Portfolio withdrawal if claiming at 62 | F10: Portfolio balance if claiming at 62 | G10: Social Security at 67 | H10: Portfoilo withdrawal if claiming at 67 | I10: Portfolio Balance if claiming at 67 | J10: Social Security at 70 | K10: Portfolio withdrawal if claiing at 70 | L10: Portfoilo balace if claiming at 70
A11: 62 | C11: =B4 -> 100000 | D11: =Main!B78 -> 23704.8 | E11: =MAX(0,C11-D11) -> 76295.2 | F11: =B2-E11 -> 923704.8 | G11: 0 | H11: =C11-G11 -> 100000 | I11: =B2-H11 -> 900000 | J11: 0 | K11: =C11-J11 -> 100000 | L11: =B2-K11 -> 900000
A12: 63 | C12: =C11*(1+$B$5) -> 103263.96 | D12: =Main!B79 -> 24297.42 | E12: =MAX(0,C12-D12) -> 78966.544 | F12: =F11*(1+$B$3)-E12 -> 881686.45 | G12: 0 | H12: =C12-G12 -> 103263.96 | I12: =I11*(1+$B$3)-H12 -> 832736.04 | J12: 0 | K12: =C12-J12 -> 103263.96 | L12: =L11*(1+$B$3)-K12 -> 832736.04
A13: 64 | C13: =C12*(1+$B$5) -> 106634.46 | D13: =Main!B80 -> 24904.855 | E13: =MAX(0,C13-D13) -> 81729.607 | F13: =F12*(1+$B$3)-E13 -> 835224.3 | G13: 0 | H13: =C13-G13 -> 106634.46 | I13: =I12*(1+$B$3)-H13 -> 759411.01 | J13: 0 | K13: =C13-J13 -> 106634.46 | L13: =L12*(1+$B$3)-K13 -> 759411.01
A14: 65 | C14: =C13*(1+$B$5) -> 110114.97 | D14: =Main!B81 -> 25527.477 | E14: =MAX(0,C14-D14) -> 84587.496 | F14: =F13*(1+$B$3)-E14 -> 784045.77 | G14: 0 | H14: =C14-G14 -> 110114.97 | I14: =I13*(1+$B$3)-H14 -> 679672.48 | J14: 0 | K14: =C14-J14 -> 110114.97 | L14: =L13*(1+$B$3)-K14 -> 679672.48
A15: 66 | C15: =C14*(1+$B$5) -> 113709.09 | D15: =Main!B82 -> 26165.664 | E15: =MAX(0,C15-D15) -> 87543.422 | F15: =F14*(1+$B$3)-E15 -> 727864.18 | G15: 0 | H15: =C15-G15 -> 113709.09 | I15: =I14*(1+$B$3)-H15 -> 593150.3 | J15: 0 | K15: =C15-J15 -> 113709.09 | L15: =L14*(1+$B$3)-K15 -> 593150.3
A16: 67 | C16: =C15*(1+$B$5) -> 117420.51 | D16: =Main!B83 -> 26819.805 | E16: =MAX(0,C16-D16) -> 90600.704 | F16: =F15*(1+$B$3)-E16 -> 666378.05 | G16: =Main!D83 -> 38314.008 | H16: =C16-G16 -> 79106.502 | I16: =I15*(1+$B$3)-H16 -> 537769.81 | J16: 0 | K16: =C16-J16 -> 117420.51 | L16: =L15*(1+$B$3)-K16 -> 499455.8
A17: 68 | C17: =C16*(1+$B$5) -> 121253.07 | D17: =Main!B84 -> 27490.301 | E17: =MAX(0,C17-D17) -> 93762.772 | F17: =F16*(1+$B$3)-E17 -> 599270.4 | G17: =Main!D84 -> 39271.858 | H17: =C17-G17 -> 81981.215 | I17: =I16*(1+$B$3)-H17 -> 477299.38 | J17: 0 | K17: =C17-J17 -> 121253.07 | L17: =L16*(1+$B$3)-K17 -> 398180.96
A18: 69 | C18: =C17*(1+$B$5) -> 125210.73 | D18: =Main!B85 -> 28177.558 | E18: =MAX(0,C18-D18) -> 97033.171 | F18: =F17*(1+$B$3)-E18 -> 526208.04 | G18: =Main!D85 -> 40253.654 | H18: =C18-G18 -> 84957.075 | I18: =I17*(1+$B$3)-H18 -> 411434.28 | J18: 0 | K18: =C18-J18 -> 125210.73 | L18: =L17*(1+$B$3)-K18 -> 288897.47
A19: 70 | C19: =C18*(1+$B$5) -> 129297.56 | D19: =Main!B86 -> 28881.997 | E19: =MAX(0,C19-D19) -> 100415.57 | F19: =F18*(1+$B$3)-E19 -> 446840.8 | G19: =Main!D86 -> 41259.996 | H19: =C19-G19 -> 88037.567 | I19: =I18*(1+$B$3)-H19 -> 339854.09 | J19: =Main!F86 -> 51162.395 | K19: =C19-J19 -> 78135.168 | L19: =L18*(1+$B$3)-K19 -> 222318.2
A20: 71 | C20: =C19*(1+$B$5) -> 133517.79 | D20: =Main!B87 -> 29604.047 | E20: =MAX(0,C20-D20) -> 103913.74 | F20: =F19*(1+$B$3)-E20 -> 360800.69 | G20: =Main!D87 -> 42291.496 | H20: =C20-G20 -> 91226.293 | I20: =I19*(1+$B$3)-H20 -> 262221.96 | J20: =Main!F87 -> 52441.455 | K20: =C20-J20 -> 81076.334 | L20: =L19*(1+$B$3)-K20 -> 150134.59
A21: 72 | C21: =C20*(1+$B$5) -> 137875.76 | D21: =Main!B88 -> 30344.148 | E21: =MAX(0,C21-D21) -> 107531.61 | F21: =F20*(1+$B$3)-E21 -> 267701.1 | G21: =Main!D88 -> 43348.783 | H21: =C21-G21 -> 94526.978 | I21: =I20*(1+$B$3)-H21 -> 178183.86 | J21: =Main!F88 -> 53752.491 | K21: =C21-J21 -> 84123.27 | L21: =L20*(1+$B$3)-K21 -> 72016.705
A22: 73 | C22: =C21*(1+$B$5) -> 142375.98 | D22: =Main!B89 -> 31102.752 | E22: =MAX(0,C22-D22) -> 111273.22 | F22: =F21*(1+$B$3)-E22 -> 167135.92 | G22: =Main!D89 -> 44432.503 | H22: =C22-G22 -> 97943.473 | I22: =I21*(1+$B$3)-H22 -> 87367.741 | J22: =Main!F89 -> 55096.303 | K22: =C22-J22 -> 87279.673 | L22: =L21*(1+$B$3)-K22 -> -12382.299
A23: 74 | C23: =C22*(1+$B$5) -> 147023.08 | D23: =Main!B90 -> 31880.321 | E23: =MAX(0,C23-D23) -> 115142.76 | F23: =F22*(1+$B$3)-E23 -> 58678.604 | G23: =Main!D90 -> 45543.315 | H23: =C23-G23 -> 101479.76 | I23: =I22*(1+$B$3)-H23 -> -10617.311 | J23: =Main!F90 -> 56473.711 | K23: =C23-J23 -> 90549.366 | L23: =L22*(1+$B$3)-K23 -> -103426.96
A24: 75 | C24: =C23*(1+$B$5) -> 151821.86 | D24: =Main!B91 -> 32677.329 | E24: =MAX(0,C24-D24) -> 119144.53 | F24: =F23*(1+$B$3)-E24 -> -58118.78 | G24: =Main!D91 -> 46681.898 | H24: =C24-G24 -> 105139.96 | I24: =I23*(1+$B$3)-H24 -> -116181.96 | J24: =Main!F91 -> 57885.554 | K24: =C24-J24 -> 93936.303 | L24: =L23*(1+$B$3)-K24 -> -201500.34
A25: 76 | C25: =C24*(1+$B$5) -> 156777.27 | D25: =Main!B92 -> 33494.262 | E25: =MAX(0,C25-D25) -> 123283.01 | F25: =F24*(1+$B$3)-E25 -> -183726.54 | G25: =Main!D92 -> 47848.945 | H25: =C25-G25 -> 108928.32 | I25: =I24*(1+$B$3)-H25 -> -229757.56 | J25: =Main!F92 -> 59332.692 | K25: =C25-J25 -> 97444.575 | L25: =L24*(1+$B$3)-K25 -> -307004.93
A26: 77 | C26: =C25*(1+$B$5) -> 161894.42 | D26: =Main!B93 -> 34331.618 | E26: =MAX(0,C26-D26) -> 127562.8 | F26: =F25*(1+$B$3)-E26 -> -318638.4 | G26: =Main!D93 -> 49045.169 | H26: =C26-G26 -> 112849.25 | I26: =I25*(1+$B$3)-H26 -> -351797.12 | J26: =Main!F93 -> 60816.01 | K26: =C26-J26 -> 101078.41 | L26: =L25*(1+$B$3)-K26 -> -420363.53
A27: 78 | C27: =C26*(1+$B$5) -> 167178.6 | D27: =Main!B94 -> 35189.909 | E27: =MAX(0,C27-D27) -> 131988.69 | F27: =F26*(1+$B$3)-E27 -> -463372.62 | G27: =Main!D94 -> 50271.298 | H27: =C27-G27 -> 116907.3 | I27: =I26*(1+$B$3)-H27 -> -482776.3 | J27: =Main!F94 -> 62336.41 | K27: =C27-J27 -> 104842.19 | L27: =L26*(1+$B$3)-K27 -> -542020.26
A28: 79 | C28: =C27*(1+$B$5) -> 172635.25 | D28: =Main!B95 -> 36069.657 | E28: =MAX(0,C28-D28) -> 136565.59 | F28: =F27*(1+$B$3)-E28 -> -618473.12 | G28: =Main!D95 -> 51528.081 | H28: =C28-G28 -> 121107.16 | I28: =I27*(1+$B$3)-H28 -> -623194.52 | J28: =Main!F95 -> 63894.82 | K28: =C28-J28 -> 108740.43 | L28: =L27*(1+$B$3)-K28 -> -672441.5
A29: 80 | C29: =C28*(1+$B$5) -> 178270 | D29: =Main!B96 -> 36971.398 | E29: =MAX(0,C29-D29) -> 141298.6 | F29: =F28*(1+$B$3)-E29 -> -784510.64 | G29: =Main!D96 -> 52816.283 | H29: =C29-G29 -> 125453.71 | I29: =I28*(1+$B$3)-H29 -> -773576.01 | J29: =Main!F96 -> 65492.191 | K29: =C29-J29 -> 112777.81 | L29: =L28*(1+$B$3)-K29 -> -812116.97
A30: 81 | C30: =C29*(1+$B$5) -> 184088.67 | D30: =Main!B97 -> 37895.683 | E30: =MAX(0,C30-D30) -> 146192.98 | F30: =F29*(1+$B$3)-E30 -> -962084.05 | G30: =Main!D97 -> 54136.69 | H30: =C30-G30 -> 129951.98 | I30: =I29*(1+$B$3)-H30 -> -934471.03 | J30: =Main!F97 -> 67129.495 | K30: =C30-J30 -> 116959.17 | L30: =L29*(1+$B$3)-K30 -> -961560.81
... A49: 100 | C49: =C48*(1+$B$5) -> 338886.37 | D49: =Main!B116 -> 60581.941 | E49: =MAX(0,C49-D49) -> 278304.43 | F49: =F48*(1+$B$3)-E49 -> -7580023.4 | G49: =Main!D116 -> 86545.629 | H49: =C49-G49 -> 252340.74 | I49: =I48*(1+$B$3)-H49 -> -6957846.6 | J49: =Main!F116 -> 107316.58 | K49: =C49-J49 -> 231569.79 | L49: =L48*(1+$B$3)-K49 -> -6563720.4

Sheet Main
A11: Full Retirement Age Benefit | B11: 2822 | D11: Average Cola since 1975 = | E11: ='SS Benefit Cal'!F3 -> 3.7294118 | N11: Breakeven Age | X11: Breakeven Age
A12: Life Expectancy | B12: 22 | D12: Average CPI since 1914 | E12: =Inflation!P123 -> 0.03263964 | N12: {=INDEX(A86:A116,MATCH(1,INDEX(--(G86:G116>=C86:C116),0),0))} -> 78 | X12: {=_xlfn.XLOOKUP(TRUE,C123:C161<=E123:E161,A123:A161,"No crossover")} -> 85
A13: Cola | B13: 0.025
A14: Rate of Return | B14: 0.04
A15: Discount Rate | B15: 0.04
A16: Retirement Funds | B16: 250000
A19: AGE | B19: Monthly benefit | C19: % change | D19: year2year change
A20: 62 | B20: =$B$11*C20 -> 1975.4 | C20: 0.7
A21: 63 | B21: =$B$11*C21 -> 2116.5 | C21: 0.75 | D21: =(B21-B20)/B20 -> 0.071428571
A22: 64 | B22: =$B$11*C22 -> 2257.6 | C22: 0.8 | D22: =(B22-B21)/B21 -> 0.066666667
A23: 65 | B23: =$B$11*C23 -> 2446.674 | C23: 0.867 | D23: =(B23-B22)/B22 -> 0.08375
A24: 66 | B24: =$B$11*C24 -> 2632.926 | C24: 0.933 | D24: =(B24-B23)/B23 -> 0.076124567
A25: 67 | B25: =$B$11*C25 -> 2822 | C25: 1 | D25: =(B25-B24)/B24 -> 0.071811361
A26: 68 | B26: =$B$11*C26 -> 3047.76 | C26: 1.08 | D26: =(B26-B25)/B25 -> 0.08
A27: 69 | B27: =$B$11*C27 -> 3273.52 | C27: 1.16 | D27: =(B27-B26)/B26 -> 0.074074074
A28: 70 | B28: =$B$11*C28 -> 3499.28 | C28: 1.24 | D28: =(B28-B27)/B27 -> 0.068965517
A32: AGE | B32: Monthy Benefit taken at 62 (Cola) | C32: Monthly Benefit taken at 67 (cola) | D32: Monthly Benefit taken at 70 (cola)
A33: 62 | B33: =B20 -> 1975.4 | F33: ="Monthly benefit with " & B13*100 & "% Cola " -> Monthly benefit with 2.5% Cola
A34: 63 | B34: =B33*(1+$B$13) -> 2024.785
A35: 64 | B35: =B34*(1+$B$13) -> 2075.4046
A36: 65 | B36: =B35*(1+$B$13) -> 2127.2897
A37: 66 | B37: =B36*(1+$B$13) -> 2180.472
A38: 67 | B38: =B37*(1+$B$13) -> 2234.9838 | C38: =B25*(1+B13)^(A25-A20) -> 3192.834
A39: 68 | B39: =B38*(1+$B$13) -> 2290.8584 | C39: =C38*(1+$B$13) -> 3272.6548
A40: 69 | B40: =B39*(1+$B$13) -> 2348.1298 | C40: =C39*(1+$B$13) -> 3354.4712
A41: 70 | B41: =B40*(1+$B$13) -> 2406.8331 | C41: =C40*(1+$B$13) -> 3438.333 | D41: =B28*(1+$B$13)^(A41-A33) -> 4263.5329
A42: 71 | B42: =B41*(1+$B$13) -> 2467.0039 | C42: =C41*(1+$B$13) -> 3524.2913 | D42: =D41*(1+$B$13) -> 4370.1212
A43: 72 | B43: =B42*(1+$B$13) -> 2528.679 | C43: =C42*(1+$B$13) -> 3612.3986 | D43: =D42*(1+$B$13) -> 4479.3742
A44: 73 | B44: =B43*(1+$B$13) -> 2591.896 | C44: =C43*(1+$B$13) -> 3702.7085 | D44: =D43*(1+$B$13) -> 4591.3586
A45: 74 | B45: =B44*(1+$B$13) -> 2656.6934 | C45: =C44*(1+$B$13) -> 3795.2763 | D45: =D44*(1+$B$13) -> 4706.1426
A46: 75 | B46: =B45*(1+$B$13) -> 2723.1107 | C46: =C45*(1+$B$13) -> 3890.1582 | D46: =D45*(1+$B$13) -> 4823.7961
A47: 76 | B47: =B46*(1+$B$13) -> 2791.1885 | C47: =C46*(1+$B$13) -> 3987.4121 | D47: =D46*(1+$B$13) -> 4944.391
A48: 77 | B48: =B47*(1+$B$13) -> 2860.9682 | C48: =C47*(1+$B$13) -> 4087.0974 | D48: =D47*(1+$B$13) -> 5068.0008
A49: 78 | B49: =B48*(1+$B$13) -> 2932.4924 | C49: =C48*(1+$B$13) -> 4189.2749 | D49: =D48*(1+$B$13) -> 5194.7008
A50: 79 | B50: =B49*(1+$B$13) -> 3005.8047 | C50: =C49*(1+$B$13) -> 4294.0067 | D50: =D49*(1+$B$13) -> 5324.5683
A51: 80 | B51: =B50*(1+$B$13) -> 3080.9498 | C51: =C50*(1+$B$13) -> 4401.3569 | D51: =D50*(1+$B$13) -> 5457.6826
A52: 81 | B52: =B51*(1+$B$13) -> 3157.9736 | C52: =C51*(1+$B$13) -> 4511.3908 | D52: =D51*(1+$B$13) -> 5594.1246
A53: 82 | B53: =B52*(1+$B$13) -> 3236.9229 | C53: =C52*(1+$B$13) -> 4624.1756 | D53: =D52*(1+$B$13) -> 5733.9777
... A71: 100 | B71: =B70*(1+$B$13) -> 5048.495 | C71: =C70*(1+$B$13) -> 7212.1358 | D71: =D70*(1+$B$13) -> 8943.0484
F73: Crossover Age
...

Sheet Frank and Bill
A2: Full Retirment Age Benefit | B2: =Main!B11 -> 2822
A3: Life Expectancy | B3: =Main!B12 -> 22
A4: Cola | B4: =Main!B13 -> 0.025 | D4: Average since 1975 = | E4: ='SS Benefit Cal'!F3 -> 3.7294118 | G4: Starting retirement funds to draw from = | H4: 250000
A5: Rate of Return | B5: 0.04 | D5: AverageCPI since 1914 | E5: =Main!E12 -> 0.03263964 | G5: Married Frank and Bill age of death | H5: 80
A6: Discount Rate | B6: =Main!B15 -> 0.04
A7: Spouse Full retirement Benefit | B7: 2500 | G7: =L7 -> Single Break even Age @ Rate of Return = 4 % | H7: {=_xlfn.XLOOKUP(TRUE,N26:N64<=O26:O64,A26:A64,"No crossover")} -> 81 | L7: ="Single Break even Age @ Rate of Return = " & $B$5*100 & " %" -> Single Break even Age @ Rate of Return = 4 %
A9: Yearly expense | B9: 23704
G11: Spouse
A12: AGE | B12: Monthy benefit | C12: % change | D12: year2year change | F12: AGE | G12: Monthy benefit | H12: % change | I12: year2year change | L12: ="Compare Saving of single Frank and Bill at rate of return of " & B5*100 & "% and Cola of " & B4*100 & "% " & "Initial Yearly Expenses = $" & B9 -> Compare Saving of single Frank and Bill at rate of return of 4% and Cola of 2.5% Initial Yearly Expenses = $23704
A13: 62 | B13: =$B$2*C13 -> 1975.4 | C13: 0.7 | F13: 62 | G13: =$B$7*H13 -> 1750 | H13: 0.7
A14: 63 | B14: =$B$2*C14 -> 2116.5 | C14: 0.75 | D14: =(B14-B13)/B13 -> 0.071428571 | F14: 63 | G14: =$B$7*H14 -> 1875 | H14: 0.75 | I14: =(G14-G13)/G13 -> 0.071428571
A15: 64 | B15: =$B$2*C15 -> 2257.6 | C15: 0.8 | D15: =(B15-B14)/B14 -> 0.066666667 | F15: 64 | G15: =$B$7*H15 -> 2000 | H15: 0.8 | I15: =(G15-G14)/G14 -> 0.066666667
A16: 65 | B16: =$B$2*C16 -> 2446.674 | C16: 0.867 | D16: =(B16-B15)/B15 -> 0.08375 | F16: 65 | G16: =$B$7*H16 -> 2167.5 | H16: 0.867 | I16: =(G16-G15)/G15 -> 0.08375
A17: 66 | B17: =$B$2*C17 -> 2632.926 | C17: 0.933 | D17: =(B17-B16)/B16 -> 0.076124567 | F17: 66 | G17: =$B$7*H17 -> 2332.5 | H17: 0.933 | I17: =(G17-G16)/G16 -> 0.076124567
A18: 67 | B18: =$B$2*C18 -> 2822 | C18: 1 | D18: =(B18-B17)/B17 -> 0.071811361 | F18: 67 | G18: =B7 -> 2500 | H18: 1 | I18: =(G18-G17)/G17 -> 0.071811361
A19: 68 | B19: =$B$2*C19 -> 3047.76 | C19: 1.08 | D19: =(B19-B18)/B18 -> 0.08 | F19: 68 | G19: =$B$7*H19 -> 2700 | H19: 1.08 | I19: =(G19-G18)/G18 -> 0.08
A20: 69 | B20: =$B$2*C20 -> 3273.52 | C20: 1.16 | D20: =(B20-B19)/B19 -> 0.074074074 | F20: 69 | G20: =$B$7*H20 -> 2900 | H20: 1.16 | I20: =(G20-G19)/G19 -> 0.074074074
A21: 70 | B21: =$B$2*C21 -> 3499.28 | C21: 1.24 | D21: =(B21-B20)/B20 -> 0.068965517 | F21: 70 | G21: =$B$7*H21 -> 3100 | H21: 1.24 | I21: =(G21-G20)/G20 -> 0.068965517
A24: Frank | G24: Bill | N24: Frank | O24: Bill
A25: Age | B25: Monthly benefit | C25: Yearly Benefit | D25: Yearly Expenses | E25: expense vs income | F25: Savings | G25: Age | H25: Monthly benefit | I25: Yearly Benefit | J25: Yearly Expenses | K25: Change to savings | L25: Saving | M25: Age | N25: Savings | O25: Savings
A26: 62 | B26: =B13 -> 1975.4 | C26: =B26*12 -> 23704.8 | D26: =B9 -> 23704 | E26: =C26-D26 -> 0.8 | F26: =$H$4*(1+$B$5) -> 260000 | G26: 62 | H26: 0 | I26: =H26*12 -> 0 | J26: =B9 -> 23704 | K26: =I26-J26 -> -23704 | L26: =($H$4)*(1+$B$5)+K26 -> 236296 | M26: 62 | N26: =F26 -> 260000 | O26: =L26 -> 236296
A27: 63 | B27: =B26*(1+$B$4) -> 2024.785 | C27: =B27*12 -> 24297.42 | D27: =D26*(1+$B$4) -> 24296.6 | E27: =C27-D27 -> 0.82 | F27: =F26*(1+$B$5)+E27 -> 270400.82 | G27: 63 | H27: 0 | I27: =H27*12 -> 0 | J27: =J26*(1+$B$4) -> 24296.6 | K27: =I27-J27 -> -24296.6 | L27: =(L26)*(1+$B$5)+K27 -> 221451.24 | M27: 63 | N27: =F27 -> 270400.82 | O27: =L27 -> 221451.24
A28: 64 | B28: =B27*(1+$B$4) -> 2075.4046 | C28: =B28*12 -> 24904.855 | D28: =D27*(1+$B$4) -> 24904.015 | E28: =C28-D28 -> 0.8405 | F28: =F27*(1+$B$5)+E28 -> 281217.69 | G28: 64 | H28: 0 | I28: =H28*12 -> 0 | J28: =J27*(1+$B$4) -> 24904.015 | K28: =I28-J28 -> -24904.015 | L28: =(L27)*(1+$B$5)+K28 -> 205405.27 | M28: 64 | N28: =F28 -> 281217.69 | O28: =L28 -> 205405.27
A29: 65 | B29: =B28*(1+$B$4) -> 2127.2897 | C29: =B29*12 -> 25527.477 | D29: =D28*(1+$B$4) -> 25526.615 | E29: =C29-D29 -> 0.8615125 | F29: =F28*(1+$B$5)+E29 -> 292467.26 | G29: 65 | H29: 0 | I29: =H29*12 -> 0 | J29: =J28*(1+$B$4) -> 25526.615 | K29: =I29-J29 -> -25526.615 | L29: =(L28)*(1+$B$5)+K29 -> 188094.87 | M29: 65 | N29: =F29 -> 292467.26 | O29: =L29 -> 188094.87
A30: 66 | B30: =B29*(1+$B$4) -> 2180.472 | C30: =B30*12 -> 26165.664 | D30: =D29*(1+$B$4) -> 26164.781 | E30: =C30-D30 -> 0.88305031 | F30: =F29*(1+$B$5)+E30 -> 304166.84 | G30: 66 | H30: 0 | I30: =H30*12 -> 0 | J30: =J29*(1+$B$4) -> 26164.781 | K30: =I30-J30 -> -26164.781 | L30: =(L29)*(1+$B$5)+K30 -> 169453.88 | M30: 66 | N30: =F30 -> 304166.84 | O30: =L30 -> 169453.88
A31: 67 | B31: =B30*(1+$B$4) -> 2234.9838 | C31: =B31*12 -> 26819.805 | D31: =D30*(1+$B$4) -> 26818.9 | E31: =C31-D31 -> 0.90512657 | F31: =F30*(1+$B$5)+E31 -> 316334.41 | G31: 67 | H31: 0 | I31: =H31*12 -> 0 | J31: =J30*(1+$B$4) -> 26818.9 | K31: =I31-J31 -> -26818.9 | L31: =(L30)*(1+$B$5)+K31 -> 149413.14 | M31: 67 | N31: =F31 -> 316334.41 | O31: =L31 -> 149413.14
A32: 68 | B32: =B31*(1+$B$4) -> 2290.8584 | C32: =B32*12 -> 27490.301 | D32: =D31*(1+$B$4) -> 27489.373 | E32: =C32-D32 -> 0.92775473 | F32: =F31*(1+$B$5)+E32 -> 328988.72 | G32: 68 | H32: 0 | I32: =H32*12 -> 0 | J32: =J31*(1+$B$4) -> 27489.373 | K32: =I32-J32 -> -27489.373 | L32: =(L31)*(1+$B$5)+K32 -> 127900.29 | M32: 68 | N32: =F32 -> 328988.72 | O32: =L32 -> 127900.29
A33: 69 | B33: =B32*(1+$B$4) -> 2348.1298 | C33: =B33*12 -> 28177.558 | D33: =D32*(1+$B$4) -> 28176.607 | E33: =C33-D33 -> 0.9509486 | F33: =F32*(1+$B$5)+E33 -> 342149.22 | G33: 69 | H33: 0 | I33: =H33*12 -> 0 | J33: =J32*(1+$B$4) -> 28176.607 | K33: =I33-J33 -> -28176.607 | L33: =(L32)*(1+$B$5)+K33 -> 104839.7 | M33: 69 | N33: =F33 -> 342149.22 | O33: =L33 -> 104839.7
A34: 70 | B34: =B33*(1+$B$4) -> 2406.8331 | C34: =B34*12 -> 28881.997 | D34: =D33*(1+$B$4) -> 28881.022 | E34: =C34-D34 -> 0.97472232 | F34: =F33*(1+$B$5)+E34 -> 355836.16 | G34: 70 | H34: =B21*(1+B4)^(70-62) -> 4263.5329 | I34: =H34*12 -> 51162.395 | J34: =J33*(1+$B$4) -> 28881.022 | K34: =I34-J34 -> 22281.372 | L34: =(L33)*(1+$B$5)+K34 -> 131314.66 | M34: 70 | N34: =F34 -> 355836.16 | O34: =L34 -> 131314.66
A35: 71 | B35: =B34*(1+$B$4) -> 2467.0039 | C35: =B35*12 -> 29604.047 | D35: =D34*(1+$B$4) -> 29603.048 | E35: =C35-D35 -> 0.99909038 | F35: =F34*(1+$B$5)+E35 -> 370070.61 | G35: 71 | H35: =H34*(1+$B$4) -> 4370.1212 | I35: =H35*12 -> 52441.455 | J35: =J34*(1+$B$4) -> 29603.048 | K35: =I35-J35 -> 22838.407 | L35: =(L34)*(1+$B$5)+K35 -> 159405.65 | M35: 71 | N35: =F35 -> 370070.61 | O35: =L35 -> 159405.65
A36: 72 | B36: =B35*(1+$B$4) -> 2528.679 | C36: =B36*12 -> 30344.148 | D36: =D35*(1+$B$4) -> 30343.124 | E36: =C36-D36 -> 1.0240676 | F36: =F35*(1+$B$5)+E36 -> 384874.46 | G36: 72 | H36: =H35*(1+$B$4) -> 4479.3742 | I36: =H36*12 -> 53752.491 | J36: =J35*(1+$B$4) -> 30343.124 | K36: =I36-J36 -> 23409.367 | L36: =(L35)*(1+$B$5)+K36 -> 189191.24 | M36: 72 | N36: =F36 -> 384874.46 | O36: =L36 -> 189191.24
A37: 73 | B37: =B36*(1+$B$4) -> 2591.896 | C37: =B37*12 -> 31102.752 | D37: =D36*(1+$B$4) -> 31101.702 | E37: =C37-D37 -> 1.0496693 | F37: =F36*(1+$B$5)+E37 -> 400270.48 | G37: 73 | H37: =H36*(1+$B$4) -> 4591.3586 | I37: =H37*12 -> 55096.303 | J37: =J36*(1+$B$4) -> 31101.702 | K37: =I37-J37 -> 23994.601 | L37: =(L36)*(1+$B$5)+K37 -> 220753.49 | M37: 73 | N37: =F37 -> 400270.48 | O37: =L37 -> 220753.49
A38: 74 | B38: =B37*(1+$B$4) -> 2656.6934 | C38: =B38*12 -> 31880.321 | D38: =D37*(1+$B$4) -> 31879.245 | E38: =C38-D38 -> 1.0759111 | F38: =F37*(1+$B$5)+E38 -> 416282.38 | G38: 74 | H38: =H37*(1+$B$4) -> 4706.1426 | I38: =H38*12 -> 56473.711 | J38: =J37*(1+$B$4) -> 31879.245 | K38: =I38-J38 -> 24594.466 | L38: =(L37)*(1+$B$5)+K38 -> 254178.1 | M38: 74 | N38: =F38 -> 416282.38 | O38: =L38 -> 254178.1
A39: 75 | B39: =B38*(1+$B$4) -> 2723.1107 | C39: =B39*12 -> 32677.329 | D39: =D38*(1+$B$4) -> 32676.226 | E39: =C39-D39 -> 1.1028088 | F39: =F38*(1+$B$5)+E39 -> 432934.78 | G39: 75 | H39: =H38*(1+$B$4) -> 4823.7961 | I39: =H39*12 -> 57885.554 | J39: =J38*(1+$B$4) -> 32676.226 | K39: =I39-J39 -> 25209.328 | L39: =(L38)*(1+$B$5)+K39 -> 289554.55 | M39: 75 | N39: =F39 -> 432934.78 | O39: =L39 -> 289554.55
A40: 76 | B40: =B39*(1+$B$4) -> 2791.1885 | C40: =B40*12 -> 33494.262 | D40: =D39*(1+$B$4) -> 33493.131 | E40: =C40-D40 -> 1.1303791 | F40: =F39*(1+$B$5)+E40 -> 450253.3 | G40: 76 | H40: =H39*(1+$B$4) -> 4944.391 | I40: =H40*12 -> 59332.692 | J40: =J39*(1+$B$4) -> 33493.131 | K40: =I40-J40 -> 25839.561 | L40: =(L39)*(1+$B$5)+K40 -> 326976.29 | M40: 76 | N40: =F40 -> 450253.3 | O40: =L40 -> 326976.29
A41: 77 | B41: =B40*(1+$B$4) -> 2860.9682 | C41: =B41*12 -> 34331.618 | D41: =D40*(1+$B$4) -> 34330.46 | E41: =C41-D41 -> 1.1586385 | F41: =F40*(1+$B$5)+E41 -> 468264.59 | G41: 77 | H41: =H40*(1+$B$4) -> 5068.0008 | I41: =H41*12 -> 60816.01 | J41: =J40*(1+$B$4) -> 34330.46 | K41: =I41-J41 -> 26485.55 | L41: =(L40)*(1+$B$5)+K41 -> 366540.9 | M41: 77 | N41: =F41 -> 468264.59 | O41: =L41 -> 366540.9
A42: 78 | B42: =B41*(1+$B$4) -> 2932.4924 | C42: =B42*12 -> 35189.909 | D42: =D41*(1+$B$4) -> 35188.721 | E42: =C42-D42 -> 1.1876045 | F42: =F41*(1+$B$5)+E42 -> 486996.36 | G42: 78 | H42: =H41*(1+$B$4) -> 5194.7008 | I42: =H42*12 -> 62336.41 | J42: =J41*(1+$B$4) -> 35188.721 | K42: =I42-J42 -> 27147.689 | L42: =(L41)*(1+$B$5)+K42 -> 408350.22 | M42: 78 | N42: =F42 -> 486996.36 | O42: =L42 -> 408350.22
A43: 79 | B43: =B42*(1+$B$4) -> 3005.8047 | C43: =B43*12 -> 36069.657 | D43: =D42*(1+$B$4) -> 36068.439 | E43: =C43-D43 -> 1.2172946 | F43: =F42*(1+$B$5)+E43 -> 506477.43 | G43: 79 | H43: =H42*(1+$B$4) -> 5324.5683 | I43: =H43*12 -> 63894.82 | J43: =J42*(1+$B$4) -> 36068.439 | K43: =I43-J43 -> 27826.381 | L43: =(L42)*(1+$B$5)+K43 -> 452510.61 | M43: 79 | N43: =F43 -> 506477.43 | O43: =L43 -> 452510.61
A44: 80 | B44: =B43*(1+$B$4) -> 3080.9498 | C44: =B44*12 -> 36971.398 | D44: =D43*(1+$B$4) -> 36970.15 | E44: =C44-D44 -> 1.247727 | F44: =F43*(1+$B$5)+E44 -> 526737.78 | G44: 80 | H44: =H43*(1+$B$4) -> 5457.6826 | I44: =H44*12 -> 65492.191 | J44: =J43*(1+$B$4) -> 36970.15 | K44: =I44-J44 -> 28522.04 | L44: =(L43)*(1+$B$5)+K44 -> 499133.08 | M44: 80 | N44: =F44 -> 526737.78 | O44: =L44 -> 499133.08
A45: 81 | B45: =B44*(1+$B$4) -> 3157.9736 | C45: =B45*12 -> 37895.683 | D45: =D44*(1+$B$4) -> 37894.404 | E45: =C45-D45 -> 1.2789201 | F45: =F44*(1+$B$5)+E45 -> 547808.57 | G45: 81 | H45: =H44*(1+$B$4) -> 5594.1246 | I45: =H45*12 -> 67129.495 | J45: =J44*(1+$B$4) -> 37894.404 | K45: =I45-J45 -> 29235.091 | L45: =(L44)*(1+$B$5)+K45 -> 548333.49 | M45: 81 | N45: =F45 -> 547808.57 | O45: =L45 -> 548333.49
...

Sheet SS Benefit Cal
A1: Social Security payout
B2: FRA | C2: =Main!B11 -> 2822
B3: Years for PV, NPV | C3: =Main!B12 -> 22 | E3: Average Cola since 1975 | F3: ='SSI cola for the year'!F5 -> 3.7294118
B4: Cola | C4: =Main!B13 -> 0.025
B5: Rate of Return | C5: =Main!B14 -> 0.04 | E5: AverageCPI since 1914 | F5: =Main!E12 -> 0.03263964
B6: Discount Rate | C6: =Main!B15 -> 0.04
B8: AGE | C8: Monthy benefit | D8: % change | E8: year2year change | G8: Monthy Benefit taken at 62 (Cola) | H8: Monthly Benefit taken at 67 (cola) | I8: Monthly Benefit taken at 70 (cola) | K8: Total take at 62. No Cola | L8: 62 yearly benefit | M8: 62 total with Cola | N8: 67 yearly benefit w Cola | O8: 67 total with Cola | P8: 70 yearly benefit w Cola | Q8: 70 total w cola | R8: 62,cola, invest,total | S8: 67, cola, invest total | T8: 70, cola, invest total | U8: Total take 62 compare to 70, cola, rate of return | V8: 70 total w cola | X8: PV take at 62, No Cola | Y8: PV take at 67, No Cola | Z8: PV take at 70, no cola | AA8: NPV take at 62, with Cola | AB8: NPV take at , 67 with Cola | AC8: NPV take at 70, with Cola | AD8: Take at 70, Loss of future gains/losses. | AE8: Take at 67, Loss of future gains/losses | AF8: PV of loss at 70 | AG8: PV of Loss at 67
B9: 62 | C9: =C2*D9 -> 1975.4 | D9: 0.7 | G9: =C9 -> 1975.4 | K9: =$C$9*12 -> 23704.8 | L9: =K9 -> 23704.8 | M9: =K9 -> 23704.8 | N9: 0 | O9: 0 | P9: 0 | Q9: 0 | R9: =M9 -> 23704.8 | S9: =O9 -> 0 | T9: =Q9 -> 0 | U9: =R9 -> 23704.8 | V9: 0 | X9: =PV($C$5,$C$3,K9,,0) -> -342560.8 | Y9: =PV($C$5,C3-5,#REF!) -> #REF! | Z9: =PV($C$5,$C$3-8,#REF!) -> #REF! | AA9: =NPV($C$5,L9:L34) -> 497144.78 | AB9: =NPV($C$5,N9:N34) -> 552028.27 | AC9: =NPV($C$5,P9:P34) -> 573489.85 | AD9: =FV($C$5,$C$3-8,,R17) -> -427382.94 | AE9: =FV($C$5,$C$3-5,,R14) -> -325147.93 | AF9: =AD9/(1+$C$5)^($C$3) -> -180336.53 | AG9: =AE9/(1+$C$5)^($C$3) -> -137197.92
B10: 63 | C10: =C2*D10 -> 2116.5 | D10: 0.75 | E10: =(C10-C9)/C9 -> 0.071428571 | G10: =G9*(1+$C$4) -> 2024.785 | K10: =K9+$K$9 -> 47409.6 | L10: =L9+(L9*$C$4) -> 24297.42 | M10: =M9+L10 -> 48002.22 | N10: 0 | O10: 0 | P10: 0 | Q10: 0 | R10: =L10+(1+$C$5)*R9 -> 48950.412 | S10: =O10 -> 0 | T10: =Q10 -> 0 | U10: =R10 -> 48950.412 | V10: 0
B11: 64 | C11: =C2*D11 -> 2257.6 | D11: 0.8 | E11: =(C11-C10)/C10 -> 0.066666667 | G11: =G10*(1+$C$4) -> 2075.4046 | K11: =K10+$K$9 -> 71114.4 | L11: =L10+(L10*$C$4) -> 24904.855 | M11: =M10+L11 -> 72907.076 | N11: 0 | O11: 0 | P11: 0 | Q11: 0 | R11: =L11+(1+$C$5)*R10 -> 75813.284 | S11: =O11 -> 0 | T11: =Q11 -> 0 | U11: =R11 -> 75813.284 | V11: 0
B12: 65 | C12: =C2*D12 -> 2446.674 | D12: 0.867 | E12: =(C12-C11)/C11 -> 0.08375 | G12: =G11*(1+$C$4) -> 2127.2897 | K12: =K11+$K$9 -> 94819.2 | L12: =L11+(L11*$C$4) -> 25527.477 | M12: =M11+L12 -> 98434.552 | N12: 0 | O12: 0 | P12: 0 | Q12: 0 | R12: =L12+(1+$C$5)*R11 -> 104373.29 | S12: =O12 -> 0 | T12: =Q12 -> 0 | U12: =R12 -> 104373.29 | V12: 0 | AF12: =FV(C5,C3,0,AF9) -> 427382.94 | AG12: =FV(C5,20,0,AG9) -> 300617.54
B13: 66 | C13: =C2*D13 -> 2632.926 | D13: 0.933 | E13: =(C13-C12)/C12 -> 0.076124567 | G13: =G12*(1+$C$4) -> 2180.472 | K13: =K12+$K$9 -> 118524 | L13: =L12+(L12*$C$4) -> 26165.664 | M13: =M12+L13 -> 124600.22 | N13: 0 | O13: 0 | P13: 0 | Q13: 0 | R13: =L13+(1+$C$5)*R12 -> 134713.89 | S13: =O13 -> 0 | T13: =Q13 -> 0 | U13: =R13 -> 134713.89 | V13: 0
B14: 67 | C14: =C2*D14 -> 2822 | D14: 1 | E14: =(C14-C13)/C13 -> 0.071811361 | G14: =G13*(1+$C$4) -> 2234.9838 | H14: =C14*(1+$C$4)^(B14-B9) -> 3192.834 | K14: =K13+$K$9 -> 142228.8 | L14: =L13+(L13*$C$4) -> 26819.805 | M14: =M13+L14 -> 151420.02 | N14: =H14*12 -> 38314.008 | O14: =N14 -> 38314.008 | P14: 0 | Q14: 0 | R14: =L14+(1+$C$5)*R13 -> 166922.25 | S14: =O14 -> 38314.008 | T14: =Q14 -> 0 | U14: =R14 -> 166922.25 | V14: 0
B15: 68 | C15: =C2*D15 -> 3047.76 | D15: 1.08 | E15: =(C15-C14)/C14 -> 0.08 | G15: =G14*(1+$C$4) -> 2290.8584 | H15: =H14*(1+$C$4) -> 3272.6548 | K15: =K14+$K$9 -> 165933.6 | L15: =L14+(L14*$C$4) -> 27490.301 | M15: =M14+L15 -> 178910.32 | N15: =H15*12 -> 39271.858 | O15: =O14+N15 -> 77585.866 | P15: 0 | Q15: 0 | R15: =L15+(1+$C$5)*R14 -> 201089.44 | S15: =(S14*(1+$C$5))+N15 -> 79118.426 | T15: =Q15 -> 0 | U15: =R15 -> 201089.44 | V15: 0
B16: 69 | C16: =C2*D16 -> 3273.52 | D16: 1.16 | E16: =(C16-C15)/C15 -> 0.074074074 | G16: =G15*(1+$C$4) -> 2348.1298 | H16: =H15*(1+$C$4) -> 3354.4712 | K16: =K15+$K$9 -> 189638.4 | L16: =L15+(L15*$C$4) -> 28177.558 | M16: =M15+L16 -> 207087.88 | N16: =H16*12 -> 40253.654 | O16: =O15+N16 -> 117839.52 | P16: 0 | Q16: 0 | R16: =L16+(1+$C$5)*R15 -> 237310.57 | S16: =(S15*(1+$C$5))+N16 -> 122536.82 | T16: =Q16 -> 0 | U16: =R16 -> 237310.57 | V16: 0
B17: 70 | C17: =C2*D17 -> 3499.28 | D17: 1.24 | E17: =(C17-C16)/C16 -> 0.068965517 | G17: =G16*(1+$C$4) -> 2406.8331 | H17: =H16*(1+$C$4) -> 3438.333 | I17: =C17*(1+$C$4)^(B17-B9) -> 4263.5329 | K17: =K16+$K$9 -> 213343.2 | L17: =L16+(L16*$C$4) -> 28881.997 | M17: =M16+L17 -> 235969.88 | N17: =H17*12 -> 41259.996 | O17: =O16+N17 -> 159099.52 | P17: =I17*12 -> 51162.395 | Q17: =P17 -> 51162.395 | R17: =R16*(1+$C$5) -> 246803 | S17: =(S16*(1+$C$5)) -> 127438.29 | T17: 0 | U17: =N17+R17 -> 288062.99 | V17: =P17 -> 51162.395
B18: 71 | G18: =G17*(1+$C$4) -> 2467.0039 | H18: =H17*(1+$C$4) -> 3524.2913 | I18: =I17*(1+$C$4) -> 4370.1212 | K18: =K17+$K$9 -> 237048 | L18: =L17+(L17*$C$4) -> 29604.047 | M18: =M17+L18 -> 265573.92 | N18: =H18*12 -> 42291.496 | O18: =O17+N18 -> 201391.01 | P18: =I18*12 -> 52441.455 | Q18: =Q17+$P$18 -> 103603.85 | R18: =R17*(1+$C$5) -> 256675.12 | S18: =(S17*(1+$C$5)) -> 132535.82 | T18: 0 | U18: =R18+K18-$K$16 -> 304084.72 | V18: =V17+P18 -> 103603.85
B19: 72 | G19: =G18*(1+$C$4) -> 2528.679 | H19: =H18*(1+$C$4) -> 3612.3986 | I19: =I18*(1+$C$4) -> 4479.3742 | K19: =K18+$K$9 -> 260752.8 | L19: =L18+(L18*$C$4) -> 30344.148 | M19: =M18+L19 -> 295918.07 | N19: =H19*12 -> 43348.783 | O19: =O18+N19 -> 244739.79 | P19: =I19*12 -> 53752.491 | Q19: =Q18+P19 -> 157356.34 | R19: =R18*(1+$C$5) -> 266942.12 | S19: =(S18*(1+$C$5)) -> 137837.25 | T19: 0 | U19: =R19+K19-$K$16 -> 338056.52 | V19: =V18+P19 -> 157356.34 | AD19: Money stays invested in an account invested at rate of return
B20: 73 | G20: =G19*(1+$C$4) -> 2591.896 | H20: =H19*(1+$C$4) -> 3702.7085 | I20: =I19*(1+$C$4) -> 4591.3586 | K20: =K19+$K$9 -> 284457.6 | L20: =L19+(L19*$C$4) -> 31102.752 | M20: =M19+L20 -> 327020.82 | N20: =H20*12 -> 44432.503 | O20: =O19+N20 -> 289172.3 | P20: =I20*12 -> 55096.303 | Q20: =Q19+P20 -> 212452.64 | R20: =R19*(1+$C$5) -> 277619.81 | S20: =(S19*(1+$C$5)) -> 143350.74 | T20: 0 | U20: =R20+K20-$K$16 -> 372439.01 | V20: =V19+P20 -> 212452.64 | AD20: How is this normalized to compare.
B21: 74 | G21: =G20*(1+$C$4) -> 2656.6934 | H21: =H20*(1+$C$4) -> 3795.2763 | I21: =I20*(1+$C$4) -> 4706.1426 | K21: =K20+$K$9 -> 308162.4 | L21: =L20+(L20*$C$4) -> 31880.321 | M21: =M20+L21 -> 358901.14 | N21: =H21*12 -> 45543.315 | O21: =O20+N21 -> 334715.61 | P21: =I21*12 -> 56473.711 | Q21: =Q20+P21 -> 268926.35 | R21: =R20*(1+$C$5) -> 288724.6 | S21: =(S20*(1+$C$5)) -> 149084.77 | T21: 0 | U21: =R21+K21-$K$16 -> 407248.6 | V21: =V20+P21 -> 268926.35
B22: 75 | G22: =G21*(1+$C$4) -> 2723.1107 | H22: =H21*(1+$C$4) -> 3890.1582 | I22: =I21*(1+$C$4) -> 4823.7961 | K22: =K21+$K$9 -> 331867.2 | L22: =L21+(L21*$C$4) -> 32677.329 | M22: =M21+L22 -> 391578.47 | N22: =H22*12 -> 46681.898 | O22: =O21+N22 -> 381397.51 | P22: =I22*12 -> 57885.554 | Q22: =Q21+P22 -> 326811.91 | R22: =R21*(1+$C$5) -> 300273.58 | S22: =(S21*(1+$C$5)) -> 155048.17 | T22: 0 | U22: =R22+K22-$K$16 -> 442502.38 | V22: =V21+P22 -> 326811.91
B23: 76 | G23: =G22*(1+$C$4) -> 2791.1885 | H23: =H22*(1+$C$4) -> 3987.4121 | I23: =I22*(1+$C$4) -> 4944.391 | K23: =K22+$K$9 -> 355572 | L23: =L22+(L22*$C$4) -> 33494.262 | M23: =M22+L23 -> 425072.74 | N23: =H23*12 -> 47848.945 | O23: =O22+N23 -> 429246.46 | P23: =I23*12 -> 59332.692 | Q23: =Q22+P23 -> 386144.6 | R23: =R22*(1+$C$5) -> 312284.53 | S23: =(S22*(1+$C$5)) -> 161250.09 | T23: 0 | U23: =R23+K23-$K$16 -> 478218.13 | V23: =V22+P23 -> 386144.6
B24: 77 | G24: =G23*(1+$C$4) -> 2860.9682 | H24: =H23*(1+$C$4) -> 4087.0974 | I24: =I23*(1+$C$4) -> 5068.0008 | K24: =K23+$K$9 -> 379276.8 | L24: =L23+(L23*$C$4) -> 34331.618 | M24: =M23+L24 -> 459404.35 | N24: =H24*12 -> 49045.169 | O24: =O23+N24 -> 478291.62 | P24: =I24*12 -> 60816.01 | Q24: =Q23+P24 -> 446960.61 | R24: =R23*(1+$C$5) -> 324775.91 | S24: =(S23*(1+$C$5)) -> 167700.1 | T24: 0 | U24: =R24+K24-$K$16 -> 514414.31 | V24: =V23+P24 -> 446960.61
B25: 78 | G25: =G24*(1+$C$4) -> 2932.4924 | H25: =H24*(1+$C$4) -> 4189.2749 | I25: =I24*(1+$C$4) -> 5194.7008 | K25: =K24+$K$9 -> 402981.6 | L25: =L24+(L24*$C$4) -> 35189.909 | M25: =M24+L25 -> 494594.26 | N25: =H25*12 -> 50271.298 | O25: =O24+N25 -> 528562.92 | P25: =I25*12 -> 62336.41 | Q25: =Q24+P25 -> 509297.02 | R25: =R24*(1+$C$5) -> 337766.94 | S25: =(S24*(1+$C$5)) -> 174408.1 | T25: 0 | U25: =R25+K25-$K$16 -> 551110.14 | V25: =V24+P25 -> 509297.02
B26: 79 | G26: =G25*(1+$C$4) -> 3005.8047 | H26: =H25*(1+$C$4) -> 4294.0067 | I26: =I25*(1+$C$4) -> 5324.5683 | K26: =K25+$K$9 -> 426686.4 | L26: =L25+(L25*$C$4) -> 36069.657 | M26: =M25+L26 -> 530663.92 | N26: =H26*12 -> 51528.081 | O26: =O25+N26 -> 580091 | P26: =I26*12 -> 63894.82 | Q26: =Q25+P26 -> 573191.84 | R26: =R25*(1+$C$5) -> 351277.62 | S26: =(S25*(1+$C$5)) -> 181384.42 | T26: 0 | U26: =R26+K26-$K$16 -> 588325.62 | V26: =V25+P26 -> 573191.84
B27: 80 | G27: =G26*(1+$C$4) -> 3080.9498 | H27: =H26*(1+$C$4) -> 4401.3569 | I27: =I26*(1+$C$4) -> 5457.6826 | K27: =K26+$K$9 -> 450391.2 | L27: =L26+(L26*$C$4) -> 36971.398 | M27: =M26+L27 -> 567635.32 | N27: =H27*12 -> 52816.283 | O27: =O26+N27 -> 632907.29 | P27: =I27*12 -> 65492.191 | Q27: =Q26+P27 -> 638684.03 | R27: =R26*(1+$C$5) -> 365328.73 | S27: =(S26*(1+$C$5)) -> 188639.8 | T27: 0 | U27: =R27+K27-$K$16 -> 626081.53 | V27: =V26+P27 -> 638684.03
B28: 81 | G28: =G27*(1+$C$4) -> 3157.9736 | H28: =H27*(1+$C$4) -> 4511.3908 | I28: =I27*(1+$C$4) -> 5594.1246 | K28: =K27+$K$9 -> 474096 | L28: =L27+(L27*$C$4) -> 37895.683 | M28: =M27+L28 -> 605531 | N28: =H28*12 -> 54136.69 | O28: =O27+N28 -> 687043.98 | P28: =I28*12 -> 67129.495 | Q28: =Q27+P28 -> 705813.53 | R28: =R27*(1+$C$5) -> 379941.88 | S28: =(S27*(1+$C$5)) -> 196185.39 | T28: 0 | U28: =R28+K28-$K$16 -> 664399.48 | V28: =V27+P28 -> 705813.53
B29: 82 | G29: =G28*(1+$C$4) -> 3236.9229 | H29: =H28*(1+$C$4) -> 4624.1756 | I29: =I28*(1+$C$4) -> 5733.9777 | K29: =K28+$K$9 -> 497800.8 | L29: =L28+(L28*$C$4) -> 38843.075 | M29: =M28+L29 -> 644374.07 | N29: =H29*12 -> 55490.107 | O29: =O28+N29 -> 742534.08 | P29: =I29*12 -> 68807.733 | Q29: =Q28+P29 -> 774621.26 | R29: =R28*(1+$C$5) -> 395139.55 | S29: =(S28*(1+$C$5)) -> 204032.81 | T29: 0 | U29: =R29+K29-$K$16 -> 703301.95 | V29: =V28+P29 -> 774621.26
B30: 83 | G30: =G29*(1+$C$4) -> 3317.846 | H30: =H29*(1+$C$4) -> 4739.78 | I30: =I29*(1+$C$4) -> 5877.3272 | K30: =K29+$K$9 -> 521505.6 | L30: =L29+(L29*$C$4) -> 39814.152 | M30: =M29+L30 -> 684188.23 | N30: =H30*12 -> 56877.36 | O30: =O29+N30 -> 799411.44 | P30: =I30*12 -> 70527.926 | Q30: =Q29+P30 -> 845149.19 | R30: =R29*(1+$C$5) -> 410945.13 | S30: =(S29*(1+$C$5)) -> 212194.12 | T30: 0 | U30: =R30+K30-$K$16 -> 742812.33 | V30: =V29+P30 -> 845149.19
B31: 84 | G31: =G30*(1+$C$4) -> 3400.7921 | H31: =H30*(1+$C$4) -> 4858.2745 | I31: =I30*(1+$C$4) -> 6024.2604 | K31: =K30+$K$9 -> 545210.4 | L31: =L30+(L30*$C$4) -> 40809.506 | M31: =M30+L31 -> 724997.73 | N31: =H31*12 -> 58299.294 | O31: =O30+N31 -> 857710.74 | P31: =I31*12 -> 72291.124 | Q31: =Q30+P31 -> 917440.31 | R31: =R30*(1+$C$5) -> 427382.94 | S31: =(S30*(1+$C$5)) -> 220681.89 | T31: 0 | U31: =R31+K31-$K$16 -> 782954.94 | V31: =V30+P31 -> 917440.31
B32: 85 | G32: =G31*(1+$C$4) -> 3485.8119 | H32: =H31*(1+$C$4) -> 4979.7313 | I32: =I31*(1+$C$4) -> 6174.8669 | K32: =K31+$K$9 -> 568915.2 | L32: =L31+(L31*$C$4) -> 41829.743 | M32: =M31+L32 -> 766827.48 | N32: =H32*12 -> 59756.776 | O32: =O31+N32 -> 917467.51 | P32: =I32*12 -> 74098.402 | Q32: =Q31+P32 -> 991538.71 | R32: =R31*(1+$C$5) -> 444478.26 | S32: =(S31*(1+$C$5)) -> 229509.16 | T32: 0 | U32: =R32+K32-$K$16 -> 823755.06 | V32: =V31+P32 -> 991538.71
... B47: 100 | G47: =G46*(1+$C$4) -> 5048.495 | H47: =H46*(1+$C$4) -> 7212.1358 | I47: =I46*(1+$C$4) -> 8943.0484 | K47: =K46+$K$9 -> 924487.2 | L47: =L46+(L46*$C$4) -> 60581.941 | M47: =M46+L47 -> 1535667.6 | N47: =H47*12 -> 86545.629 | O47: =O46+N47 -> 2015810.5 | P47: =I47*12 -> 107316.58 | Q47: =Q46+P47 -> 2353484 | R47: =R46*(1+$C$5) -> 800480.23 | S47: =(S46*(1+$C$5)) -> 413333.03 | T47: 0 | U47: =R47+K47-$K$16 -> 1535329 | V47: =V46+P47 -> 2353484

Sheet RMD Tables 2025
B4: Table III | G4: Discount Rate | H4: =Main!B14 -> 0.04
B5: (Uniform Lifetime) | G5: Balance at 72 | H5: 2000000
B6: (For Use by: | G6: Cola | H6: =Main!B13 -> 0.025
B7: Unmarried Owners,
B8: Married Owners Whose Spouses Aren't More Than 10 Years Younger, and
B9: Married Owners Whose Spouses Aren't the Sole Beneficiaries of Their IRAs)
B11: Age | C11: Distribution Period | D11: Age | E11: Distribution Period | H11: Balance at 72 | J11: RMD | K11: Cola Adjusted Initial RMD | M11: Balance/RMD %
B12: 72 | C12: 27.4 | D12: 97 | E12: 7.8 | G12: 72 | H12: =H5 -> 2000000 | I12: =C12 -> 27.4 | J12: =H12/I12 -> 72992.701 | M12: =J12/H12 -> 0.03649635
B13: 73 | C13: 26.5 | D13: 98 | E13: 7.3 | G13: 73 | H13: =(H12-J12)*(1+$H$4) -> 2004087.6 | I13: =C13 -> 26.5 | J13: =H13/I13 -> 75625.947 | K13: =J12*(1+$H$6) -> 74817.518 | M13: =J13/H13 -> 0.037735849
B14: 74 | C14: 25.5 | D14: 99 | E14: 6.8 | G14: 74 | H14: =(H13-J13)*(1+$H$4) -> 2005600.1 | I14: =C14 -> 25.5 | J14: =H14/I14 -> 78650.985 | K14: =K13*(1+$H$6) -> 76687.956 | M14: =J14/H14 -> 0.039215686
B15: 75 | C15: 24.6 | D15: 100 | E15: 6.4 | G15: 75 | H15: =(H14-J14)*(1+$H$4) -> 2004027.1 | I15: =C15 -> 24.6 | J15: =H15/I15 -> 81464.516 | K15: =K14*(1+$H$6) -> 78605.155 | M15: =J15/H15 -> 0.040650407
B16: 76 | C16: 23.7 | D16: 101 | E16: 6 | G16: 76 | H16: =(H15-J15)*(1+$H$4) -> 1999465.1 | I16: =C16 -> 23.7 | J16: =H16/I16 -> 84365.615 | K16: =K15*(1+$H$6) -> 80570.284 | M16: =J16/H16 -> 0.042194093
B17: 77 | C17: 22.9 | D17: 102 | E17: 5.6 | G17: 77 | H17: =(H16-J16)*(1+$H$4) -> 1991703.4 | I17: =C17 -> 22.9 | J17: =H17/I17 -> 86973.949 | K17: =K16*(1+$H$6) -> 82584.541 | M17: =J17/H17 -> 0.043668122
B18: 78 | C18: 22 | D18: 103 | E18: 5.2 | G18: 78 | H18: =(H17-J17)*(1+$H$4) -> 1980918.7 | I18: =C18 -> 22 | J18: =H18/I18 -> 90041.758 | K18: =K17*(1+$H$6) -> 84649.155 | M18: =J18/H18 -> 0.045454545
B19: 79 | C19: 21.1 | D19: 104 | E19: 4.9 | G19: 79 | H19: =(H18-J18)*(1+$H$4) -> 1966512 | I19: =C19 -> 21.1 | J19: =H19/I19 -> 93199.62 | K19: =K18*(1+$H$6) -> 86765.383 | M19: =J19/H19 -> 0.047393365
B20: 80 | C20: 20.2 | D20: 105 | E20: 4.6 | G20: 80 | H20: =(H19-J19)*(1+$H$4) -> 1948244.9 | I20: =C20 -> 20.2 | J20: =H20/I20 -> 96447.766 | K20: =K19*(1+$H$6) -> 88934.518 | M20: =J20/H20 -> 0.04950495
B21: 81 | C21: 19.4 | D21: 106 | E21: 4.3 | G21: 81 | H21: =(H20-J20)*(1+$H$4) -> 1925869 | I21: =C21 -> 19.4 | J21: =H21/I21 -> 99271.597 | K21: =K20*(1+$H$6) -> 91157.881 | M21: =J21/H21 -> 0.051546392
B22: 82 | C22: 18.5 | D22: 107 | E22: 4.1 | G22: 82 | H22: =(H21-J21)*(1+$H$4) -> 1899661.3 | I22: =C22 -> 18.5 | J22: =H22/I22 -> 102684.39 | K22: =K21*(1+$H$6) -> 93436.828 | M22: =J22/H22 -> 0.054054054
B23: 83 | C23: 17.7 | D23: 108 | E23: 3.9 | G23: 83 | H23: =(H22-J22)*(1+$H$4) -> 1868856 | I23: =C23 -> 17.7 | J23: =H23/I23 -> 105585.08 | K23: =K22*(1+$H$6) -> 95772.749 | M23: =J23/H23 -> 0.056497175
B24: 84 | C24: 16.8 | D24: 109 | E24: 3.7 | G24: 84 | H24: =(H23-J23)*(1+$H$4) -> 1833801.7 | I24: =C24 -> 16.8 | J24: =H24/I24 -> 109154.86 | K24: =K23*(1+$H$6) -> 98167.067 | M24: =J24/H24 -> 0.05952381
B25: 85 | C25: 16 | D25: 110 | E25: 3.5 | G25: 85 | H25: =(H24-J24)*(1+$H$4) -> 1793632.7 | I25: =C25 -> 16 | J25: =H25/I25 -> 112102.05 | K25: =K24*(1+$H$6) -> 100621.24 | M25: =J25/H25 -> 0.0625
... B34: 94 | C34: 9.5 | D34: 119 | E34: 2.3 | G34: 94 | H34: =(H33-J33)*(1+$H$4) -> 1219282.4 | I34: =C34 -> 9.5 | J34: =H34/I34 -> 128345.52 | K34: =K33*(1+$H$6) -> 125662.15 | M34: =J34/H34 -> 0.10526316
B35: 95 | C35: 8.9 | D35: 120 and over | E35: 2 | G35: 95 | H35: =(H34-J34)*(1+$H$4) -> 1134574.4 | I35: =C35 -> 8.9 | J35: =H35/I35 -> 127480.27 | K35: =K34*(1+$H$6) -> 128803.7 | M35: =J35/H35 -> 0.11235955
B36: 96 | C36: 8.4 | G36: 96 | H36: =(H35-J35)*(1+$H$4) -> 1047377.9 | I36: =C36 -> 8.4 | J36: =H36/I36 -> 124687.84 | K36: =K35*(1+$H$6) -> 132023.79 | M36: =J36/H36 -> 0.11904762
B37: 97 | G37: 97 | H37: =(H36-J36)*(1+$H$4) -> 959597.62 | I37: =E12 -> 7.8 | J37: =H37/I37 -> 123025.34 | K37: =K36*(1+$H$6) -> 135324.39 | M37: =J37/H37 -> 0.12820513
B38: 98 | G38: 98 | H38: =(H37-J37)*(1+$H$4) -> 870035.18 | I38: =E13 -> 7.3 | J38: =H38/I38 -> 119182.9 | K38: =K37*(1+$H$6) -> 138707.5 | M38: =J38/H38 -> 0.1369863
B39: 99 | G39: 99 | H39: =(H38-J38)*(1+$H$4) -> 780886.37 | I39: =E14 -> 6.8 | J39: =H39/I39 -> 114836.23 | K39: =K38*(1+$H$6) -> 142175.18 | M39: =J39/H39 -> 0.14705882
B40: 100 | G40: 100 | H40: =(H39-J39)*(1+$H$4) -> 692692.14 | I40: =E15 -> 6.4 | J40: =H40/I40 -> 108233.15 | K40: =K39*(1+$H$6) -> 145729.56 | M40: =J40/H40 -> 0.15625
B41: 101 | G41: 101 | H41: =(H40-J40)*(1+$H$4) -> 607837.35 | I41: =E16 -> 6 | J41: =H41/I41 -> 101306.23 | K41: =K40*(1+$H$6) -> 149372.8 | M41: =J41/H41 -> 0.16666667
B42: 102 | G42: 102 | H42: =(H41-J41)*(1+$H$4) -> 526792.37 | I42: =E17 -> 5.6 | J42: =H42/I42 -> 94070.067 | K42: =K41*(1+$H$6) -> 153107.12 | M42: =J42/H42 -> 0.17857143
B43: 103 | G43: 103 | H43: =(H42-J42)*(1+$H$4) -> 450031.2 | I43: =E18 -> 5.2 | J43: =H43/I43 -> 86544.461 | K43: =K42*(1+$H$6) -> 156934.8 | M43: =J43/H43 -> 0.19230769
B44: 104 | G44: 104 | H44: =(H43-J43)*(1+$H$4) -> 378026.21 | I44: =E19 -> 4.9 | J44: =H44/I44 -> 77148.206 | K44: =K43*(1+$H$6) -> 160858.17 | M44: =J44/H44 -> 0.20408163
B45: 105 | G45: 105 | H45: =(H44-J44)*(1+$H$4) -> 312913.12 | I45: =E20 -> 4.6 | J45: =H45/I45 -> 68024.592 | K45: =K44*(1+$H$6) -> 164879.62 | M45: =J45/H45 -> 0.2173913
B46: 106 | G46: 106 | H46: =(H45-J45)*(1+$H$4) -> 254684.07 | I46: =E21 -> 4.3 | J46: =H46/I46 -> 59228.854 | K46: =K45*(1+$H$6) -> 169001.62 | M46: =J46/H46 -> 0.23255814
B47: 107 | G47: 107 | H47: =(H46-J46)*(1+$H$4) -> 203273.43 | I47: =E22 -> 4.1 | J47: =H47/I47 -> 49578.884 | K47: =K46*(1+$H$6) -> 173226.66 | M47: =J47/H47 -> 0.24390244
B48: 108 | G48: 108 | H48: =(H47-J47)*(1+$H$4) -> 159842.32 | I48: =E23 -> 3.9 | J48: =H48/I48 -> 40985.211 | K48: =K47*(1+$H$6) -> 177557.32 | M48: =J48/H48 -> 0.25641026
... B60: 120 | G60: 120 | H60: =(H59-J59)*(1+$H$4) -> 1981.9551 | I60: =E35 -> 2 | J60: =H60/I60 -> 990.97756 | K60: =K59*(1+$H$6) -> 238794.86 | M60: =J60/H60 -> 0.5

Sheet Cpi_index_inflation_montly_1925
A1: Series ID | B1: Year | C1: Period | D1: Label | E1: Value | F1: 12-Month % Change
A2: CUUR0000SA0 | B2: 1925 | C2: M01 | D2: 9133 | E2: 17.3 | F2: 0
A3: CUUR0000SA0 | B3: 1925 | C3: M02 | D3: 9164 | E3: 17.2 | F3: 0
A4: CUUR0000SA0 | B4: 1925 | C4: M03 | D4: 9192 | E4: 17.3 | F4: 1.2
A5: CUUR0000SA0 | B5: 1925 | C5: M04 | D5: 9223 | E5: 17.2 | F5: 1.2
A6: CUUR0000SA0 | B6: 1925 | C6: M05 | D6: 9253 | E6: 17.3 | F6: 1.8
A7: CUUR0000SA0 | B7: 1925 | C7: M06 | D7: 9284 | E7: 17.5 | F7: 2.9
A8: CUUR0000SA0 | B8: 1925 | C8: M07 | D8: 9314 | E8: 17.7 | F8: 3.5
A9: CUUR0000SA0 | B9: 1925 | C9: M08 | D9: 9345 | E9: 17.7 | F9: 4.1
A10: CUUR0000SA0 | B10: 1925 | C10: M09 | D10: 9376 | E10: 17.7 | F10: 3.5
A11: CUUR0000SA0 | B11: 1925 | C11: M10 | D11: 9406 | E11: 17.7 | F11: 2.9
A12: CUUR0000SA0 | B12: 1925 | C12: M11 | D12: 9437 | E12: 18 | F12: 4.7
A13: CUUR0000SA0 | B13: 1925 | C13: M12 | D13: 9467 | E13: 17.9 | F13: 3.5
... A1009: CUUR0000SA0 | B1009: 2008 | C1009: M12 | D1009: 39783 | E1009: 210.228 | F1009: 0.1
A1010: CUUR0000SA0 | B1010: 2009 | C1010: M01 | D1010: 39814 | E1010: 211.143
A1011: CUUR0000SA0 | B1011: 2009 | C1011: M02 | D1011: 39845 | E1011: 212.193
A1012: CUUR0000SA0 | B1012: 2009 | C1012: M03 | D1012: 39873 | E1012: 212.709
A1013: CUUR0000SA0 | B1013: 2009 | C1013: M04 | D1013: 39904 | E1013: 213.24
A1014: CUUR0000SA0 | B1014: 2009 | C1014: M05 | D1014: 39934 | E1014: 213.856
A1015: CUUR0000SA0 | B1015: 2009 | C1015: M06 | D1015: 39965 | E1015: 215.693
A1016: CUUR0000SA0 | B1016: 2009 | C1016: M07 | D1016: 39995 | E1016: 215.351
A1017: CUUR0000SA0 | B1017: 2009 | C1017: M08 | D1017: 40026 | E1017: 215.834
A1018: CUUR0000SA0 | B1018: 2009 | C1018: M09 | D1018: 40057 | E1018: 215.969
A1019: CUUR0000SA0 | B1019: 2009 | C1019: M10 | D1019: 40087 | E1019: 216.177
A1020: CUUR0000SA0 | B1020: 2009 | C1020: M11 | D1020: 40118 | E1020: 216.33
A1021: CUUR0000SA0 | B1021: 2009 | C1021: M12 | D1021: 40148 | E1021: 215.949
A1022: CUUR0000SA0 | B1022: 2010 | C1022: M01 | D1022: 40179 | E1022: 216.687 | F1022: 2.6
A1023: CUUR0000SA0 | B1023: 2010 | C1023: M02 | D1023: 40210 | E1023: 216.741 | F1023: 2.1
A1024: CUUR0000SA0 | B1024: 2010 | C1024: M03 | D1024: 40238 | E1024: 217.631 | F1024: 2.3
A1025: CUUR0000SA0 | B1025: 2010 | C1025: M04 | D1025: 40269 | E1025: 218.009 | F1025: 2.2
A1026: CUUR0000SA0 | B1026: 2010 | C1026: M05 | D1026: 40299 | E1026: 218.178 | F1026: 2
A1027: CUUR0000SA0 | B1027: 2010 | C1027: M06 | D1027: 40330 | E1027: 217.965 | F1027: 1.1
A1028: CUUR0000SA0 | B1028: 2010 | C1028: M07 | D1028: 40360 | E1028: 218.011 | F1028: 1.2
A1029: CUUR0000SA0 | B1029: 2010 | C1029: M08 | D1029: 40391 | E1029: 218.312 | F1029: 1.1
A1030: CUUR0000SA0 | B1030: 2010 | C1030: M09 | D1030: 40422 | E1030: 218.439 | F1030: 1.1
A1031: CUUR0000SA0 | B1031: 2010 | C1031: M10 | D1031: 40452 | E1031: 218.711 | F1031: 1.2
A1032: CUUR0000SA0 | B1032: 2010 | C1032: M11 | D1032: 40483 | E1032: 218.803 | F1032: 1.1
A1033: CUUR0000SA0 | B1033: 2010 | C1033: M12 | D1033: 40513 | E1033: 219.179 | F1033: 1.5
A1034: CUUR0000SA0 | B1034: 2011 | C1034: M01 | D1034: 40544 | E1034: 220.223
A1035: CUUR0000SA0 | B1035: 2011 | C1035: M02 | D1035: 40575 | E1035: 221.309
...

Sheet Inflation
C4: Table of Historical Inflation Rates in Percent
C5: (1914-2025)
C7: Year | D7: Jan | E7: Feb | F7: Mar | G7: Apr | H7: May | I7: Jun | J7: Jul | K7: Aug | L7: Sep | M7: Oct | N7: Nov | O7: Dec | P7: Ave
C8: 1914 | D8: 2 | E8: 1 | F8: 1 | G8: 0 | H8: 2.1 | I8: 1 | J8: 1 | K8: 3 | L8: 2 | M8: 1 | N8: 1 | O8: 1 | P8: 1
C9: 1915 | D9: 1 | E9: 1 | F9: 0 | G9: 2 | H9: 2 | I9: 2 | J9: 1 | K9: -1 | L9: -1 | M9: 1 | N9: 1 | O9: 2 | P9: 1
C10: 1916 | D10: 3 | E10: 4 | F10: 6.1 | G10: 6 | H10: 5.9 | I10: 6.9 | J10: 6.9 | K10: 7.9 | L10: 9.9 | M10: 10.8 | N10: 11.7 | O10: 12.6 | P10: 7.9
C11: 1917 | D11: 12.5 | E11: 15.4 | F11: 14.3 | G11: 18.9 | H11: 19.6 | I11: 20.4 | J11: 18.5 | K11: 19.3 | L11: 19.8 | M11: 19.5 | N11: 17.4 | O11: 18.1 | P11: 17.4
C12: 1918 | D12: 19.7 | E12: 17.5 | F12: 16.7 | G12: 12.7 | H12: 13.3 | I12: 13.1 | J12: 18 | K12: 18.5 | L12: 18 | M12: 18.5 | N12: 20.7 | O12: 20.4 | P12: 18
C13: 1919 | D13: 17.9 | E13: 14.9 | F13: 17.1 | G13: 17.6 | H13: 16.6 | I13: 15 | J13: 15.2 | K13: 14.9 | L13: 13.4 | M13: 13.1 | N13: 13.5 | O13: 14.5 | P13: 14.6
C14: 1920 | D14: 17 | E14: 20.4 | F14: 20.1 | G14: 21.6 | H14: 21.9 | I14: 23.7 | J14: 19.5 | K14: 14.7 | L14: 12.4 | M14: 9.9 | N14: 7 | O14: 2.6 | P14: 15.6
C15: 1921 | D15: -1.6 | E15: -5.6 | F15: -7.1 | G15: -10.8 | H15: -14.1 | I15: -15.8 | J15: -14.9 | K15: -12.8 | L15: -12.5 | M15: -12.1 | N15: -12.1 | O15: -10.8 | P15: -10.5
C16: 1922 | D16: -11.1 | E16: -8.2 | F16: -8.7 | G16: -7.7 | H16: -5.6 | I16: -5.1 | J16: -5.1 | K16: -6.2 | L16: -5.1 | M16: -4.6 | N16: -3.4 | O16: -2.3 | P16: -6.1
C17: 1923 | D17: -0.6 | E17: -0.6 | F17: 0.6 | G17: 1.2 | H17: 1.2 | I17: 1.8 | J17: 2.4 | K17: 3 | L17: 3.6 | M17: 3.6 | N17: 3 | O17: 2.4 | P17: 1.8
C18: 1924 | D18: 3 | E18: 2.4 | F18: 1.8 | G18: 0.6 | H18: 0.6 | I18: 0 | J18: -0.6 | K18: -0.6 | L18: -0.6 | M18: -0.6 | N18: -0.6 | O18: 0 | P18: 0
C19: 1925 | D19: 0 | E19: 0 | F19: 1.2 | G19: 1.2 | H19: 1.8 | I19: 2.9 | J19: 3.5 | K19: 4.1 | L19: 3.5 | M19: 2.9 | N19: 4.7 | O19: 3.5 | P19: 2.3
... C118: 2024 | D118: 3.1 | E118: 3.2 | F118: 3.5 | G118: 3.4 | H118: 3.3 | I118: 3 | J118: 2.9 | K118: 2.5 | L118: 2.4 | M118: 2.6 | N118: 2.7 | O118: 2.9 | P118: 2.9
C119: 2025 | D119: 3 | E119: 2.8 | F119: 2.4 | G119: 2.3 | H119: 2.4 | I119: 2.7 | J119: 2.7 | K119: 2.9 | L119: 3 | M119: – (*) | N119: 2.7 | O119: Avail.
O120: Jan.
O121: 13
P123: =(SUM(P8:P118)/111)/100 -> 0.03263964

Sheet Sheet1
B3: todays $1000
B5: future amout | C5: years | D5: discount rate | E5: PV
B6: 1000 | C6: 5 | D6: 0.0326 | E6: =PV(D6,C6,B6,B6) -> -5397.7098
C9: =B6/(1+D6)^C6 -> 851.80345

Sheet Sheet2

Sheet index test
A1: CPI
B3: Base year | C3: Test Year | D3: Factor | E3: base price | H3: Equivalent cost
B4: =Cpi_index_inflation_montly_1925!E1154 -> 261.582 | C4: =Cpi_index_inflation_montly_1925!E1166 -> 281.148 | D4: =B4/C4 -> 0.93040676 | E4: 1000 | F4: =E4*D4 -> 930.40676 | H4: =C4/B4 -> 1.0747987 | I4: =E4*H4 -> 1074.7987

Sheet Salarys 2024
C2: State | D2: Average Salary | E2: Median Salary | F2: color
C3: Alabama | D3: 53400 | E3: 41350 | F3: R
C4: Alaska | D4: 69880 | E4: 56140 | F4: R
C5: Arizona | D5: 63040 | E5: 47680 | F5: R
C6: Arkansas | D6: 51250 | E6: 39060 | F6: R
C7: California | D7: 76960 | E7: 54030 | F7: B
C8: Colorado | D8: 71960 | E8: 54050 | F8: B
C9: Connecticut | D9: 73740 | E9: 56130 | F9: B
C10: Delaware | D10: 65990 | E10: 49280 | F10: B
C11: Florida | D11: 60210 | E11: 45070 | F11: R
C12: Georgia | D12: 61250 | E12: 45480 | F12: R
C13: Hawaii | D13: 65030 | E13: 50510 | F13: B
C14: Idaho | D14: 55640 | E14: 44240 | F14: R
... C20: Louisiana | D20: 53440 | E20: 41320 | F20: R
C21: Maine | D21: 60000 | E21: 47590
C22: Maryland | D22: 73620 | E22: 55810
C23: Massachusetts | D23: 80330 | E23: 60690
C24: Michigan | D24: 60600 | E24: 46940 | F24: R
C25: Minnesota | D25: 66700 | E25: 50880
C26: Mississippi | D26: 47570 | E26: 37500 | F26: R
C27: Missouri | D27: 57580 | E27: 45080 | F27: R
C28: Montana | D28: 55920 | E28: 45690 | F28: R
C29: Nebraska | D29: 58080 | E29: 46440 | F29: R
C30: Nevada | D30: 58900 | E30: 44810 | F30: R
C31: New Hampshire | D31: 66110 | E31: 49980
C32: New Jersey | D32: 73980 | E32: 54860
C33: New Mexico | D33: 57520 | E33: 43620
C34: New York | D34: 78620 | E34: 56840
C35: North Carolina | D35: 59730 | E35: 45440 | F35: R
C36: North Dakota | D36: 59050 | E36: 48830 | F36: R
C37: Ohio | D37: 59890 | E37: 46690 | F37: R
C38: Oklahoma | D38: 53450 | E38: 41480 | F38: R
C39: Oregon | D39: 66710 | E39: 50010
C40: Pennsylvania | D40: 61920 | E40: 47430 | F40: R
C41: Rhode Island | D41: 66610 | E41: 50970
C42: South Carolina | D42: 54250 | E42: 42220 | F42: R
C43: South Dakota | D43: 53230 | E43: 43680 | F43: R
C44: Tennessee | D44: 56030 | E44: 43820 | F44: R
C45: Texas | D45: 61240 | E45: 45970 | F45: R
C46: Utah | D46: 61070 | E46: 47020 | F46: R
...

Sheet s&p_returns
B1: Year | C1: Return in %
B2: Column1 | C2: Column2
B3: 2024 | C3: 25.02
B4: 2023 | C4: 26.29
B5: 2022 | C5: -18.11
B6: 2021 | C6: 28.71
B7: 2020 | C7: 18.4
B8: 2019 | C8: 31.49
B9: 2018 | C9: -4.38
B10: 2017 | C10: 21.83
B11: 2016 | C11: 11.96
B12: 2015 | C12: 1.38
B13: 2014 | C13: 13.69
B14: 2013 | C14: 32.39
... B101: 1926 | C101: 11.62

Sheet SSI cola for the year
B3: Social Security Cost-Of-Living Adjustments
B4: Year | C4: COLA
B5: 1975 | C5: 8 | E5: Average | F5: =SUM(C5:C55)/((B55-B5)+1) -> 3.7294118
B6: 1976 | C6: 6.4
B7: 1977 | C7: 5.9
B8: 1978 | C8: 6.5
B9: 1979 | C9: 9.9
B10: 1980 | C10: 14.3
B11: 1981 | C11: 11.2
B12: 1982 | C12: 7.4
B13: 1983 | C13: 3.5
B14: 1984 | C14: 3.5
B15: 1985 | C15: 3.1
B16: 1986 | C16: 1.3
B17: 1987 | C17: 4.2
... B28: 1998 | C28: 1.3
B29: 1999 a | C29: 2.5
B30: 2000 | C30: 3.5
B31: 2001 | C31: 2.6
B32: 2002 | C32: 1.4
B33: 2003 | C33: 2.1
B34: 2004 | C34: 2.7
B35: 2005 | C35: 4.1
B36: 2006 | C36: 3.3
B37: 2007 | C37: 2.3
B38: 2008 | C38: 5.8
B39: 2009 | C39: 0
B40: 2010 | C40: 0
B41: 2011 | C41: 3.6
... B55: 2025 | C55: 2.8
