Workbook
Name TimeSeries: 'SSI cola for the year'!$B$3

Sheet Main
A3: Full Retirement Age Benefit | B3: 2822
A4: Life Expectancy | B4: 22
A5: Cola | B5: 0.025 | D5: Average Cola since 1975 = | E5: ='SS Benefit Cal'!F3 -> 3.7294118
A6: Rate of Return | B6: 0.025 | D6: Average CPI since 1914 | E6: =Inflation!P123 -> 0.03263964
A7: Discount Rate | B7: 0.025
A10: AGE | B10: Monthly benefit | C10: % change | D10: year2year change
A11: 62 | B11: =$B$3*C11 -> 1975.4 | C11: 0.7
A12: 63 | B12: =$B$3*C12 -> 2116.5 | C12: 0.75 | D12: =(B12-B11)/B11 -> 0.071428571
A13: 64 | B13: =$B$3*C13 -> 2257.6 | C13: 0.8 | D13: =(B13-B12)/B12 -> 0.066666667
A14: 65 | B14: =$B$3*C14 -> 2446.674 | C14: 0.867 | D14: =(B14-B13)/B13 -> 0.08375
A15: 66 | B15: =$B$3*C15 -> 2632.926 | C15: 0.933 | D15: =(B15-B14)/B14 -> 0.076124567
A16: 67 | B16: =$B$3*C16 -> 2822 | C16: 1 | D16: =(B16-B15)/B15 -> 0.071811361 | G16: ="Monthly benefit with " & B5*100 & "% Cola " -> Monthly benefit with 2.5% Cola
A17: 68 | B17: =$B$3*C17 -> 3047.76 | C17: 1.08 | D17: =(B17-B16)/B16 -> 0.08
A18: 69 | B18: =$B$3*C18 -> 3273.52 | C18: 1.16 | D18: =(B18-B17)/B17 -> 0.074074074
A19: 70 | B19: =$B$3*C19 -> 3499.28 | C19: 1.24 | D19: =(B19-B18)/B18 -> 0.068965517
B23: Monthy Benefit taken at 62 (Cola) | C23: Monthly Benefit taken at 67 (cola) | D23: Monthly Benefit taken at 70 (cola)
A24: 62 | B24: =B11 -> 1975.4
A25: 63 | B25: =B24*(1+$B$5) -> 2024.785
A26: 64 | B26: =B25*(1+$B$5) -> 2075.4046
A27: 65 | B27: =B26*(1+$B$5) -> 2127.2897
A28: 66 | B28: =B27*(1+$B$5) -> 2180.472
A29: 67 | B29: =B28*(1+$B$5) -> 2234.9838 | C29: =B16 -> 2822
A30: 68 | B30: =B29*(1+$B$5) -> 2290.8584 | C30: =C29*(1+$B$5) -> 2892.55
A31: 69 | B31: =B30*(1+$B$5) -> 2348.1298 | C31: =C30*(1+$B$5) -> 2964.8637
A32: 70 | B32: =B31*(1+$B$5) -> 2406.8331 | C32: =C31*(1+$B$5) -> 3038.9853 | D32: =B19 -> 3499.28
A33: 71 | B33: =B32*(1+$B$5) -> 2467.0039 | C33: =C32*(1+$B$5) -> 3114.96 | D33: =D32*(1+$B$5) -> 3586.762
A34: 72 | B34: =B33*(1+$B$5) -> 2528.679 | C34: =C33*(1+$B$5) -> 3192.834 | D34: =D33*(1+$B$5) -> 3676.431
A35: 73 | B35: =B34*(1+$B$5) -> 2591.896 | C35: =C34*(1+$B$5) -> 3272.6548 | D35: =D34*(1+$B$5) -> 3768.3418
A36: 74 | B36: =B35*(1+$B$5) -> 2656.6934 | C36: =C35*(1+$B$5) -> 3354.4712 | D36: =D35*(1+$B$5) -> 3862.5504
A37: 75 | B37: =B36*(1+$B$5) -> 2723.1107 | C37: =C36*(1+$B$5) -> 3438.333 | D37: =D36*(1+$B$5) -> 3959.1141
A38: 76 | B38: =B37*(1+$B$5) -> 2791.1885 | C38: =C37*(1+$B$5) -> 3524.2913 | D38: =D37*(1+$B$5) -> 4058.092
A39: 77 | B39: =B38*(1+$B$5) -> 2860.9682 | C39: =C38*(1+$B$5) -> 3612.3986 | D39: =D38*(1+$B$5) -> 4159.5443
A40: 78 | B40: =B39*(1+$B$5) -> 2932.4924 | C40: =C39*(1+$B$5) -> 3702.7085 | D40: =D39*(1+$B$5) -> 4263.5329
A41: 79 | B41: =B40*(1+$B$5) -> 3005.8047 | C41: =C40*(1+$B$5) -> 3795.2763 | D41: =D40*(1+$B$5) -> 4370.1212
A42: 80 | B42: =B41*(1+$B$5) -> 3080.9498 | C42: =C41*(1+$B$5) -> 3890.1582 | D42: =D41*(1+$B$5) -> 4479.3742
A43: 81 | B43: =B42*(1+$B$5) -> 3157.9736 | C43: =C42*(1+$B$5) -> 3987.4121 | D43: =D42*(1+$B$5) -> 4591.3586
A44: 82 | B44: =B43*(1+$B$5) -> 3236.9229 | C44: =C43*(1+$B$5) -> 4087.0974 | D44: =D43*(1+$B$5) -> 4706.1426
... A62: 100 | B62: =B61*(1+$B$5) -> 5048.495 | C62: =C61*(1+$B$5) -> 6374.4771 | D62: =D61*(1+$B$5) -> 7339.9763
A65: Age | B65: Total take at 62. No Cola | C65: Total take at 67 No cola | D65: 70 total No Cola | F65: Yearly payment no Cola take@62 | G65: Yearly payment no Cola take@67 | H65: Yearly payment no Cola take@70
A66: 62 | B66: =B24*12 -> 23704.8 | F66: =B66 -> 23704.8 | G66: =0 -> 0 | H66: 0
...

Sheet SS Benefit Cal
A1: Social Security payout
B2: FRA | C2: =Main!B3 -> 2822
B3: Years for PV, NPV | C3: =Main!B4 -> 22 | E3: Average Cola since 1975 | F3: ='SSI cola for the year'!F5 -> 3.7294118
B4: Cola | C4: =Main!B5 -> 0.025
B5: Rate of Return | C5: =Main!B6 -> 0.025 | E5: AverageCPI since 1914 | F5: =Main!E6 -> 0.03263964
B6: Discount Rate | C6: =Main!B7 -> 0.025
B8: AGE | C8: Monthy benefit | D8: % change | E8: year2year change | G8: Monthy Benefit taken at 62 (Cola) | H8: Monthly Benefit taken at 67 (cola) | I8: Monthly Benefit taken at 70 (cola) | K8: Total take at 62. No Cola | L8: Total take at 67 No cola | M8: 70 total No Cola | N8: 62 yearly benefit | O8: 62 total with Cola | P8: 67 yearly benefit w Cola | Q8: 67 total with Cola | R8: 70 yearly benefit w Cola | S8: 70 total w cola | T8: 62,cola, invest,total | U8: 67, cola, invest total | V8: 70, cola, invest total | W8: Total take 62 compare to 70, cola, rate of return | X8: 70 total w cola | Z8: PV take at 62, No Cola | AA8: PV take at 67, No Cola | AB8: PV take at 70, no cola | AC8: NPV take at 62, with Cola | AD8: NPV take at , 67 with Cola | AE8: NPV take at 70, with Cola | AF8: Take at 70, Loss of future gains/losses. | AG8: Take at 67, Loss of future gains/losses | AH8: PV of loss at 70 | AI8: PV of Loss at 67
B9: 62 | C9: =C2*D9 -> 1975.4 | D9: 0.7 | G9: =C9 -> 1975.4 | K9: =$C$9*12 -> 23704.8 | N9: =K9 -> 23704.8 | O9: =K9 -> 23704.8 | P9: 0 | Q9: 0 | R9: 0 | S9: 0 | T9: =O9 -> 23704.8 | U9: =Q9 -> 0 | V9: =S9 -> 0 | W9: =T9 -> 23704.8 | X9: 0 | Z9: =PV($C$5,$C$3,K9,,0) -> -397420.77 | AA9: =PV($C$5,C3-5,L14) -> -464349.86 | AB9: =PV($C$5,$C$3-8,M17) -> -490917.3 | AC9: =NPV($C$5,N9:N34) -> 601292.49 | AD9: =NPV($C$5,P9:P34) -> 613217.24 | AE9: =NPV($C$5,R9:R34) -> 605226.11 | AF9: =FV($C$5,$C$3-8,,T17) -> -326476.05 | AG9: =FV($C$5,$C$3-5,,T14) -> -244857.03 | AH9: =AF9/(1+$C$5)^($C$3) -> -189638.4 | AI9: =AG9/(1+$C$5)^($C$3) -> -142228.8
B10: 63 | C10: =C2*D10 -> 2116.5 | D10: 0.75 | E10: =(C10-C9)/C9 -> 0.071428571 | G10: =G9*(1+$C$4) -> 2024.785 | K10: =K9+$K$9 -> 47409.6 | N10: =N9+(N9*$C$4) -> 24297.42 | O10: =O9+N10 -> 48002.22 | P10: 0 | Q10: 0 | R10: 0 | S10: 0 | T10: =N10+(1+$C$5)*T9 -> 48594.84 | U10: =Q10 -> 0 | V10: =S10 -> 0 | W10: =T10 -> 48594.84 | X10: 0
B11: 64 | C11: =C2*D11 -> 2257.6 | D11: 0.8 | E11: =(C11-C10)/C10 -> 0.066666667 | G11: =G10*(1+$C$4) -> 2075.4046 | K11: =K10+$K$9 -> 71114.4 | N11: =N10+(N10*$C$4) -> 24904.855 | O11: =O10+N11 -> 72907.076 | P11: 0 | Q11: 0 | R11: 0 | S11: 0 | T11: =N11+(1+$C$5)*T10 -> 74714.566 | U11: =Q11 -> 0 | V11: =S11 -> 0 | W11: =T11 -> 74714.566 | X11: 0
B12: 65 | C12: =C2*D12 -> 2446.674 | D12: 0.867 | E12: =(C12-C11)/C11 -> 0.08375 | G12: =G11*(1+$C$4) -> 2127.2897 | K12: =K11+$K$9 -> 94819.2 | N12: =N11+(N11*$C$4) -> 25527.477 | O12: =O11+N12 -> 98434.552 | P12: 0 | Q12: 0 | R12: 0 | S12: 0 | T12: =N12+(1+$C$5)*T11 -> 102109.91 | U12: =Q12 -> 0 | V12: =S12 -> 0 | W12: =T12 -> 102109.91 | X12: 0 | AH12: =FV(C5,C3,0,AH9) -> 326476.05 | AI12: =FV(C5,20,0,AI9) -> 233058.45
B13: 66 | C13: =C2*D13 -> 2632.926 | D13: 0.933 | E13: =(C13-C12)/C12 -> 0.076124567 | G13: =G12*(1+$C$4) -> 2180.472 | K13: =K12+$K$9 -> 118524 | N13: =N12+(N12*$C$4) -> 26165.664 | O13: =O12+N13 -> 124600.22 | P13: 0 | Q13: 0 | R13: 0 | S13: 0 | T13: =N13+(1+$C$5)*T12 -> 130828.32 | U13: =Q13 -> 0 | V13: =S13 -> 0 | W13: =T13 -> 130828.32 | X13: 0
B14: 67 | C14: =C2*D14 -> 2822 | D14: 1 | E14: =(C14-C13)/C13 -> 0.071811361 | G14: =G13*(1+$C$4) -> 2234.9838 | H14: =$C$14 -> 2822 | K14: =K13+$K$9 -> 142228.8 | L14: =C14*12 -> 33864 | N14: =N13+(N13*$C$4) -> 26819.805 | O14: =O13+N14 -> 151420.02 | P14: =L14 -> 33864 | Q14: =L14 -> 33864 | R14: 0 | S14: 0 | T14: =N14+(1+$C$5)*T13 -> 160918.83 | U14: =Q14 -> 33864 | V14: =S14 -> 0 | W14: =T14 -> 160918.83 | X14: 0
B15: 68 | C15: =C2*D15 -> 3047.76 | D15: 1.08 | E15: =(C15-C14)/C14 -> 0.08 | G15: =G14*(1+$C$4) -> 2290.8584 | H15: =H14*(1+$C$4) -> 2892.55 | K15: =K14+$K$9 -> 165933.6 | L15: =L14+$L$14 -> 67728 | N15: =N14+(N14*$C$4) -> 27490.301 | O15: =O14+N15 -> 178910.32 | P15: =P14+P14*$C$4 -> 34710.6 | Q15: =Q14+P15 -> 68574.6 | R15: 0 | S15: 0 | T15: =N15+(1+$C$5)*T14 -> 192432.1 | U15: =(U14*(1+$C$5))+P15 -> 69421.2 | V15: =S15 -> 0 | W15: =T15 -> 192432.1 | X15: 0
B16: 69 | C16: =C2*D16 -> 3273.52 | D16: 1.16 | E16: =(C16-C15)/C15 -> 0.074074074 | G16: =G15*(1+$C$4) -> 2348.1298 | H16: =H15*(1+$C$4) -> 2964.8637 | K16: =K15+$K$9 -> 189638.4 | L16: =L15+$L$14 -> 101592 | N16: =N15+(N15*$C$4) -> 28177.558 | O16: =O15+N16 -> 207087.88 | P16: =P15+P15*$C$4 -> 35578.365 | Q16: =Q15+P16 -> 104152.96 | R16: 0 | S16: 0 | T16: =N16+(1+$C$5)*T15 -> 225420.46 | U16: =(U15*(1+$C$5))+P16 -> 106735.1 | V16: =S16 -> 0 | W16: =T16 -> 225420.46 | X16: 0
B17: 70 | C17: =C2*D17 -> 3499.28 | D17: 1.24 | E17: =(C17-C16)/C16 -> 0.068965517 | G17: =G16*(1+$C$4) -> 2406.8331 | H17: =H16*(1+$C$4) -> 3038.9853 | I17: =C17 -> 3499.28 | K17: =K16+$K$9 -> 213343.2 | L17: =L16+$L$14 -> 135456 | M17: =C17*12 -> 41991.36 | N17: =N16+(N16*$C$4) -> 28881.997 | O17: =O16+N17 -> 235969.88 | P17: =P16+P16*$C$4 -> 36467.824 | Q17: =Q16+P17 -> 140620.79 | R17: =M17 -> 41991.36 | S17: =M17 -> 41991.36 | T17: =T16*(1+$C$5) -> 231055.98 | U17: =(U16*(1+$C$5)) -> 109403.47 | V17: 0 | W17: =P17+T17 -> 267523.8 | X17: =R17 -> 41991.36
B18: 71 | G18: =G17*(1+$C$4) -> 2467.0039 | H18: =H17*(1+$C$4) -> 3114.96 | I18: =I17*(1+$C$4) -> 3586.762 | K18: =K17+$K$9 -> 237048 | L18: =L17+$L$14 -> 169320 | M18: =M17+$M$17 -> 83982.72 | N18: =N17+(N17*$C$4) -> 29604.047 | O18: =O17+N18 -> 265573.92 | P18: =P17+P17*$C$4 -> 37379.52 | Q18: =Q17+P18 -> 178000.31 | R18: =R17 +R17*$C$4 -> 43041.144 | S18: =S17+$R$18 -> 85032.504 | T18: =T17*(1+$C$5) -> 236832.38 | U18: =(U17*(1+$C$5)) -> 112138.56 | V18: 0 | W18: =T18+K18-$K$16 -> 284241.98 | X18: =X17+R18 -> 85032.504
B19: 72 | G19: =G18*(1+$C$4) -> 2528.679 | H19: =H18*(1+$C$4) -> 3192.834 | I19: =I18*(1+$C$4) -> 3676.431 | K19: =K18+$K$9 -> 260752.8 | L19: =L18+$L$14 -> 203184 | M19: =M18+$M$17 -> 125974.08 | N19: =N18+(N18*$C$4) -> 30344.148 | O19: =O18+N19 -> 295918.07 | P19: =P18+P18*$C$4 -> 38314.008 | Q19: =Q18+P19 -> 216314.32 | R19: =R18 +R18*$C$4 -> 44117.173 | S19: =S18+R19 -> 129149.68 | T19: =T18*(1+$C$5) -> 242753.18 | U19: =(U18*(1+$C$5)) -> 114942.02 | V19: 0 | W19: =T19+K19-$K$16 -> 313867.58 | X19: =X18+R19 -> 129149.68 | AF19: Money stays invested in an account invested at rate of return
B20: 73 | G20: =G19*(1+$C$4) -> 2591.896 | H20: =H19*(1+$C$4) -> 3272.6548 | I20: =I19*(1+$C$4) -> 3768.3418 | K20: =K19+$K$9 -> 284457.6 | L20: =L19+$L$14 -> 237048 | M20: =M19+$M$17 -> 167965.44 | N20: =N19+(N19*$C$4) -> 31102.752 | O20: =O19+N20 -> 327020.82 | P20: =P19+P19*$C$4 -> 39271.858 | Q20: =Q19+P20 -> 255586.17 | R20: =R19 +R19*$C$4 -> 45220.102 | S20: =S19+R20 -> 174369.78 | T20: =T19*(1+$C$5) -> 248822.01 | U20: =(U19*(1+$C$5)) -> 117815.57 | V20: 0 | W20: =T20+K20-$K$16 -> 343641.21 | X20: =X19+R20 -> 174369.78 | AF20: How is this normalized to compare.
B21: 74 | G21: =G20*(1+$C$4) -> 2656.6934 | H21: =H20*(1+$C$4) -> 3354.4712 | I21: =I20*(1+$C$4) -> 3862.5504 | K21: =K20+$K$9 -> 308162.4 | L21: =L20+$L$14 -> 270912 | M21: =M20+$M$17 -> 209956.8 | N21: =N20+(N20*$C$4) -> 31880.321 | O21: =O20+N21 -> 358901.14 | P21: =P20+P20*$C$4 -> 40253.654 | Q21: =Q20+P21 -> 295839.83 | R21: =R20 +R20*$C$4 -> 46350.604 | S21: =S20+R21 -> 220720.38 | T21: =T20*(1+$C$5) -> 255042.56 | U21: =(U20*(1+$C$5)) -> 120760.96 | V21: 0 | W21: =T21+K21-$K$16 -> 373566.56 | X21: =X20+R21 -> 220720.38
B22: 75 | G22: =G21*(1+$C$4) -> 2723.1107 | H22: =H21*(1+$C$4) -> 3438.333 | I22: =I21*(1+$C$4) -> 3959.1141 | K22: =K21+$K$9 -> 331867.2 | L22: =L21+$L$14 -> 304776 | M22: =M21+$M$17 -> 251948.16 | N22: =N21+(N21*$C$4) -> 32677.329 | O22: =O21+N22 -> 391578.47 | P22: =P21+P21*$C$4 -> 41259.996 | Q22: =Q21+P22 -> 337099.82 | R22: =R21 +R21*$C$4 -> 47509.37 | S22: =S21+R22 -> 268229.75 | T22: =T21*(1+$C$5) -> 261418.63 | U22: =(U21*(1+$C$5)) -> 123779.99 | V22: 0 | W22: =T22+K22-$K$16 -> 403647.43 | X22: =X21+R22 -> 268229.75
B23: 76 | G23: =G22*(1+$C$4) -> 2791.1885 | H23: =H22*(1+$C$4) -> 3524.2913 | I23: =I22*(1+$C$4) -> 4058.092 | K23: =K22+$K$9 -> 355572 | L23: =L22+$L$14 -> 338640 | M23: =M22+$M$17 -> 293939.52 | N23: =N22+(N22*$C$4) -> 33494.262 | O23: =O22+N23 -> 425072.74 | P23: =P22+P22*$C$4 -> 42291.496 | Q23: =Q22+P23 -> 379391.32 | R23: =R22 +R22*$C$4 -> 48697.104 | S23: =S22+R23 -> 316926.86 | T23: =T22*(1+$C$5) -> 267954.09 | U23: =(U22*(1+$C$5)) -> 126874.49 | V23: 0 | W23: =T23+K23-$K$16 -> 433887.69 | X23: =X22+R23 -> 316926.86
B24: 77 | G24: =G23*(1+$C$4) -> 2860.9682 | H24: =H23*(1+$C$4) -> 3612.3986 | I24: =I23*(1+$C$4) -> 4159.5443 | K24: =K23+$K$9 -> 379276.8 | L24: =L23+$L$14 -> 372504 | M24: =M23+$M$17 -> 335930.88 | N24: =N23+(N23*$C$4) -> 34331.618 | O24: =O23+N24 -> 459404.35 | P24: =P23+P23*$C$4 -> 43348.783 | Q24: =Q23+P24 -> 422740.1 | R24: =R23 +R23*$C$4 -> 49914.531 | S24: =S23+R24 -> 366841.39 | T24: =T23*(1+$C$5) -> 274652.95 | U24: =(U23*(1+$C$5)) -> 130046.35 | V24: 0 | W24: =T24+K24-$K$16 -> 464291.35 | X24: =X23+R24 -> 366841.39
B25: 78 | G25: =G24*(1+$C$4) -> 2932.4924 | H25: =H24*(1+$C$4) -> 3702.7085 | I25: =I24*(1+$C$4) -> 4263.5329 | K25: =K24+$K$9 -> 402981.6 | L25: =L24+$L$14 -> 406368 | M25: =M24+$M$17 -> 377922.24 | N25: =N24+(N24*$C$4) -> 35189.909 | O25: =O24+N25 -> 494594.26 | P25: =P24+P24*$C$4 -> 44432.503 | Q25: =Q24+P25 -> 467172.61 | R25: =R24 +R24*$C$4 -> 51162.395 | S25: =S24+R25 -> 418003.78 | T25: =T24*(1+$C$5) -> 281519.27 | U25: =(U24*(1+$C$5)) -> 133297.51 | V25: 0 | W25: =T25+K25-$K$16 -> 494862.47 | X25: =X24+R25 -> 418003.78
B26: 79 | G26: =G25*(1+$C$4) -> 3005.8047 | H26: =H25*(1+$C$4) -> 3795.2763 | I26: =I25*(1+$C$4) -> 4370.1212 | K26: =K25+$K$9 -> 426686.4 | L26: =L25+$L$14 -> 440232 | M26: =M25+$M$17 -> 419913.6 | N26: =N25+(N25*$C$4) -> 36069.657 | O26: =O25+N26 -> 530663.92 | P26: =P25+P25*$C$4 -> 45543.315 | Q26: =Q25+P26 -> 512715.92 | R26: =R25 +R25*$C$4 -> 52441.455 | S26: =S25+R26 -> 470445.24 | T26: =T25*(1+$C$5) -> 288557.25 | U26: =(U25*(1+$C$5)) -> 136629.95 | V26: 0 | W26: =T26+K26-$K$16 -> 525605.25 | X26: =X25+R26 -> 470445.24
B27: 80 | G27: =G26*(1+$C$4) -> 3080.9498 | H27: =H26*(1+$C$4) -> 3890.1582 | I27: =I26*(1+$C$4) -> 4479.3742 | K27: =K26+$K$9 -> 450391.2 | L27: =L26+$L$14 -> 474096 | M27: =M26+$M$17 -> 461904.96 | N27: =N26+(N26*$C$4) -> 36971.398 | O27: =O26+N27 -> 567635.32 | P27: =P26+P26*$C$4 -> 46681.898 | Q27: =Q26+P27 -> 559397.82 | R27: =R26 +R26*$C$4 -> 53752.491 | S27: =S26+R27 -> 524197.73 | T27: =T26*(1+$C$5) -> 295771.18 | U27: =(U26*(1+$C$5)) -> 140045.69 | V27: 0 | W27: =T27+K27-$K$16 -> 556523.98 | X27: =X26+R27 -> 524197.73
B28: 81 | G28: =G27*(1+$C$4) -> 3157.9736 | H28: =H27*(1+$C$4) -> 3987.4121 | I28: =I27*(1+$C$4) -> 4591.3586 | K28: =K27+$K$9 -> 474096 | L28: =L27+$L$14 -> 507960 | M28: =M27+$M$17 -> 503896.32 | N28: =N27+(N27*$C$4) -> 37895.683 | O28: =O27+N28 -> 605531 | P28: =P27+P27*$C$4 -> 47848.945 | Q28: =Q27+P28 -> 607246.76 | R28: =R27 +R27*$C$4 -> 55096.303 | S28: =S27+R28 -> 579294.03 | T28: =T27*(1+$C$5) -> 303165.46 | U28: =(U27*(1+$C$5)) -> 143546.84 | V28: 0 | W28: =T28+K28-$K$16 -> 587623.06 | X28: =X27+R28 -> 579294.03
B29: 82 | G29: =G28*(1+$C$4) -> 3236.9229 | H29: =H28*(1+$C$4) -> 4087.0974 | I29: =I28*(1+$C$4) -> 4706.1426 | K29: =K28+$K$9 -> 497800.8 | L29: =L28+$L$14 -> 541824 | M29: =M28+$M$17 -> 545887.68 | N29: =N28+(N28*$C$4) -> 38843.075 | O29: =O28+N29 -> 644374.07 | P29: =P28+P28*$C$4 -> 49045.169 | Q29: =Q28+P29 -> 656291.93 | R29: =R28 +R28*$C$4 -> 56473.711 | S29: =S28+R29 -> 635767.74 | T29: =T28*(1+$C$5) -> 310744.6 | U29: =(U28*(1+$C$5)) -> 147135.51 | V29: 0 | W29: =T29+K29-$K$16 -> 618907 | X29: =X28+R29 -> 635767.74
B30: 83 | G30: =G29*(1+$C$4) -> 3317.846 | H30: =H29*(1+$C$4) -> 4189.2749 | I30: =I29*(1+$C$4) -> 4823.7961 | K30: =K29+$K$9 -> 521505.6 | L30: =L29+$L$14 -> 575688 | M30: =M29+$M$17 -> 587879.04 | N30: =N29+(N29*$C$4) -> 39814.152 | O30: =O29+N30 -> 684188.23 | P30: =P29+P29*$C$4 -> 50271.298 | Q30: =Q29+P30 -> 706563.23 | R30: =R29 +R29*$C$4 -> 57885.554 | S30: =S29+R30 -> 693653.3 | T30: =T29*(1+$C$5) -> 318513.21 | U30: =(U29*(1+$C$5)) -> 150813.9 | V30: 0 | W30: =T30+K30-$K$16 -> 650380.41 | X30: =X29+R30 -> 693653.3
B31: 84 | G31: =G30*(1+$C$4) -> 3400.7921 | H31: =H30*(1+$C$4) -> 4294.0067 | I31: =I30*(1+$C$4) -> 4944.391 | K31: =K30+$K$9 -> 545210.4 | L31: =L30+$L$14 -> 609552 | M31: =M30+$M$17 -> 629870.4 | N31: =N30+(N30*$C$4) -> 40809.506 | O31: =O30+N31 -> 724997.73 | P31: =P30+P30*$C$4 -> 51528.081 | Q31: =Q30+P31 -> 758091.31 | R31: =R30 +R30*$C$4 -> 59332.692 | S31: =S30+R31 -> 752985.99 | T31: =T30*(1+$C$5) -> 326476.05 | U31: =(U30*(1+$C$5)) -> 154584.24 | V31: 0 | W31: =T31+K31-$K$16 -> 682048.05 | X31: =X30+R31 -> 752985.99
B32: 85 | G32: =G31*(1+$C$4) -> 3485.8119 | H32: =H31*(1+$C$4) -> 4401.3569 | I32: =I31*(1+$C$4) -> 5068.0008 | K32: =K31+$K$9 -> 568915.2 | L32: =L31+$L$14 -> 643416 | M32: =M31+$M$17 -> 671861.76 | N32: =N31+(N31*$C$4) -> 41829.743 | O32: =O31+N32 -> 766827.48 | P32: =P31+P31*$C$4 -> 52816.283 | Q32: =Q31+P32 -> 810907.6 | R32: =R31 +R31*$C$4 -> 60816.01 | S32: =S31+R32 -> 813802 | T32: =T31*(1+$C$5) -> 334637.95 | U32: =(U31*(1+$C$5)) -> 158448.85 | V32: 0 | W32: =T32+K32-$K$16 -> 713914.75 | X32: =X31+R32 -> 813802
... B47: 100 | G47: =G46*(1+$C$4) -> 5048.495 | H47: =H46*(1+$C$4) -> 6374.4771 | I47: =I46*(1+$C$4) -> 7339.9763 | K47: =K46+$K$9 -> 924487.2 | L47: =L46+$L$14 -> 1151376 | M47: =M46+$M$17 -> 1301732.2 | N47: =N46+(N46*$C$4) -> 60581.941 | O47: =O46+N47 -> 1535667.6 | P47: =P46+P46*$C$4 -> 76493.726 | Q47: =Q46+P47 -> 1781682.7 | R47: =R46 +R46*$C$4 -> 88079.715 | S47: =S46+R47 -> 1931613.9 | T47: =T46*(1+$C$5) -> 484655.52 | U47: =(U46*(1+$C$5)) -> 229481.18 | V47: 0 | W47: =T47+K47-$K$16 -> 1219504.3 | X47: =X46+R47 -> 1931613.9

Sheet Frank and Bill
A2: Full Retirment Age Benefit | B2: =Main!B3 -> 2822
A3: Life Expectancy | B3: =Main!B4 -> 22
A4: Cola | B4: =Main!B5 -> 0.025 | D4: Average since 1975 = | E4: ='SS Benefit Cal'!F3 -> 3.7294118 | G4: Starting retirement funds to draw from = | H4: 250000
A5: Rate of Return | B5: 0.0326 | D5: AverageCPI since 1914 | E5: =Main!E6 -> 0.03263964 | G5: Frank and Bill age of death | H5: 80
A6: Discount Rate | B6: =Main!B7 -> 0.025
A7: Spouse Full retirement Benefit | B7: 2500
A9: Yearly expense | B9: 23704
G10: Spouse
A11: AGE | B11: Monthy benefit | C11: % change | D11: year2year change | F11: AGE | G11: Monthy benefit | H11: % change | I11: year2year change
A12: 62 | B12: =$B$2*C12 -> 1975.4 | C12: 0.7 | F12: 62 | G12: =$B$7*H12 -> 1750 | H12: 0.7
A13: 63 | B13: =$B$2*C13 -> 2116.5 | C13: 0.75 | D13: =(B13-B12)/B12 -> 0.071428571 | F13: 63 | G13: =$B$7*H13 -> 1875 | H13: 0.75 | I13: =(G13-G12)/G12 -> 0.071428571
A14: 64 | B14: =$B$2*C14 -> 2257.6 | C14: 0.8 | D14: =(B14-B13)/B13 -> 0.066666667 | F14: 64 | G14: =$B$7*H14 -> 2000 | H14: 0.8 | I14: =(G14-G13)/G13 -> 0.066666667
A15: 65 | B15: =$B$2*C15 -> 2446.674 | C15: 0.867 | D15: =(B15-B14)/B14 -> 0.08375 | F15: 65 | G15: =$B$7*H15 -> 2167.5 | H15: 0.867 | I15: =(G15-G14)/G14 -> 0.08375
A16: 66 | B16: =$B$2*C16 -> 2632.926 | C16: 0.933 | D16: =(B16-B15)/B15 -> 0.076124567 | F16: 66 | G16: =$B$7*H16 -> 2332.5 | H16: 0.933 | I16: =(G16-G15)/G15 -> 0.076124567
A17: 67 | B17: =$B$2*C17 -> 2822 | C17: 1 | D17: =(B17-B16)/B16 -> 0.071811361 | F17: 67 | G17: =B7 -> 2500 | H17: 1 | I17: =(G17-G16)/G16 -> 0.071811361
A18: 68 | B18: =$B$2*C18 -> 3047.76 | C18: 1.08 | D18: =(B18-B17)/B17 -> 0.08 | F18: 68 | G18: =$B$7*H18 -> 2700 | H18: 1.08 | I18: =(G18-G17)/G17 -> 0.08
A19: 69 | B19: =$B$2*C19 -> 3273.52 | C19: 1.16 | D19: =(B19-B18)/B18 -> 0.074074074 | F19: 69 | G19: =$B$7*H19 -> 2900 | H19: 1.16 | I19: =(G19-G18)/G18 -> 0.074074074
A20: 70 | B20: =$B$2*C20 -> 3499.28 | C20: 1.24 | D20: =(B20-B19)/B19 -> 0.068965517 | F20: 70 | G20: =$B$7*H20 -> 3100 | H20: 1.24 | I20: =(G20-G19)/G19 -> 0.068965517
A23: Frank | G23: Bill | N23: Frank | O23: Bill
A24: Age | B24: Monthly benefit | C24: Yearly Benefit | D24: Yearly Expenses | E24: expense vs income | F24: Savings | G24: Age | H24: Monthly benefit | I24: Yearly Benefit | J24: Yearly Expenses | K24: Change to savings | L24: Saving | M24: Age | N24: Savings | O24: Savings
A25: 62 | B25: =B12 -> 1975.4 | C25: =B25*12 -> 23704.8 | D25: =B9 -> 23704 | E25: =C25-D25 -> 0.8 | F25: =$H$4*(1+$B$5) -> 258150 | G25: 62 | H25: 0 | I25: =H25*12 -> 0 | J25: =B9 -> 23704 | K25: =I25-J25 -> -23704 | L25: =($H$4)*(1+$B$5)+K25 -> 234446 | M25: 62 | N25: =F25 -> 258150 | O25: =L25 -> 234446
A26: 63 | B26: =B25*(1+$B$4) -> 2024.785 | C26: =B26*12 -> 24297.42 | D26: =D25*(1+$B$4) -> 24296.6 | E26: =C26-D26 -> 0.82 | F26: =F25*(1+$B$5)+E26 -> 266566.51 | G26: 63 | H26: 0 | I26: =H26*12 -> 0 | J26: =J25*(1+$B$4) -> 24296.6 | K26: =I26-J26 -> -24296.6 | L26: =(L25)*(1+$B$5)+K26 -> 217792.34 | M26: 63 | N26: =F26 -> 266566.51 | O26: =L26 -> 217792.34
A27: 64 | B27: =B26*(1+$B$4) -> 2075.4046 | C27: =B27*12 -> 24904.855 | D27: =D26*(1+$B$4) -> 24904.015 | E27: =C27-D27 -> 0.8405 | F27: =F26*(1+$B$5)+E27 -> 275257.42 | G27: 64 | H27: 0 | I27: =H27*12 -> 0 | J27: =J26*(1+$B$4) -> 24904.015 | K27: =I27-J27 -> -24904.015 | L27: =(L26)*(1+$B$5)+K27 -> 199988.35 | M27: 64 | N27: =F27 -> 275257.42 | O27: =L27 -> 199988.35
A28: 65 | B28: =B27*(1+$B$4) -> 2127.2897 | C28: =B28*12 -> 25527.477 | D28: =D27*(1+$B$4) -> 25526.615 | E28: =C28-D28 -> 0.8615125 | F28: =F27*(1+$B$5)+E28 -> 284231.67 | G28: 65 | H28: 0 | I28: =H28*12 -> 0 | J28: =J27*(1+$B$4) -> 25526.615 | K28: =I28-J28 -> -25526.615 | L28: =(L27)*(1+$B$5)+K28 -> 180981.36 | M28: 65 | N28: =F28 -> 284231.67 | O28: =L28 -> 180981.36
A29: 66 | B29: =B28*(1+$B$4) -> 2180.472 | C29: =B29*12 -> 26165.664 | D29: =D28*(1+$B$4) -> 26164.781 | E29: =C29-D29 -> 0.88305031 | F29: =F28*(1+$B$5)+E29 -> 293498.51 | G29: 66 | H29: 0 | I29: =H29*12 -> 0 | J29: =J28*(1+$B$4) -> 26164.781 | K29: =I29-J29 -> -26164.781 | L29: =(L28)*(1+$B$5)+K29 -> 160716.57 | M29: 66 | N29: =F29 -> 293498.51 | O29: =L29 -> 160716.57
A30: 67 | B30: =B29*(1+$B$4) -> 2234.9838 | C30: =B30*12 -> 26819.805 | D30: =D29*(1+$B$4) -> 26818.9 | E30: =C30-D30 -> 0.90512657 | F30: =F29*(1+$B$5)+E30 -> 303067.46 | G30: 67 | H30: 0 | I30: =H30*12 -> 0 | J30: =J29*(1+$B$4) -> 26818.9 | K30: =I30-J30 -> -26818.9 | L30: =(L29)*(1+$B$5)+K30 -> 139137.03 | M30: 67 | N30: =F30 -> 303067.46 | O30: =L30 -> 139137.03
A31: 68 | B31: =B30*(1+$B$4) -> 2290.8584 | C31: =B31*12 -> 27490.301 | D31: =D30*(1+$B$4) -> 27489.373 | E31: =C31-D31 -> 0.92775473 | F31: =F30*(1+$B$5)+E31 -> 312948.39 | G31: 68 | H31: 0 | I31: =H31*12 -> 0 | J31: =J30*(1+$B$4) -> 27489.373 | K31: =I31-J31 -> -27489.373 | L31: =(L30)*(1+$B$5)+K31 -> 116183.53 | M31: 68 | N31: =F31 -> 312948.39 | O31: =L31 -> 116183.53
A32: 69 | B32: =B31*(1+$B$4) -> 2348.1298 | C32: =B32*12 -> 28177.558 | D32: =D31*(1+$B$4) -> 28176.607 | E32: =C32-D32 -> 0.9509486 | F32: =F31*(1+$B$5)+E32 -> 323151.46 | G32: 69 | H32: 0 | I32: =H32*12 -> 0 | J32: =J31*(1+$B$4) -> 28176.607 | K32: =I32-J32 -> -28176.607 | L32: =(L31)*(1+$B$5)+K32 -> 91794.502 | M32: 69 | N32: =F32 -> 323151.46 | O32: =L32 -> 91794.502
A33: 70 | B33: =B32*(1+$B$4) -> 2406.8331 | C33: =B33*12 -> 28881.997 | D33: =D32*(1+$B$4) -> 28881.022 | E33: =C33-D33 -> 0.97472232 | F33: =F32*(1+$B$5)+E33 -> 333687.17 | G33: 70 | H33: =B20 -> 3499.28 | I33: =H33*12 -> 41991.36 | J33: =J32*(1+$B$4) -> 28881.022 | K33: =I33-J33 -> 13110.338 | L33: =(L32)*(1+$B$5)+K33 -> 107897.34 | M33: 70 | N33: =F33 -> 333687.17 | O33: =L33 -> 107897.34
A34: 71 | B34: =B33*(1+$B$4) -> 2467.0039 | C34: =B34*12 -> 29604.047 | D34: =D33*(1+$B$4) -> 29603.048 | E34: =C34-D34 -> 0.99909038 | F34: =F33*(1+$B$5)+E34 -> 344566.37 | G34: 71 | H34: =H33*(1+$B$4) -> 3586.762 | I34: =H34*12 -> 43041.144 | J34: =J33*(1+$B$4) -> 29603.048 | K34: =I34-J34 -> 13438.096 | L34: =(L33)*(1+$B$5)+K34 -> 124852.89 | M34: 71 | N34: =F34 -> 344566.37 | O34: =L34 -> 124852.89
A35: 72 | B35: =B34*(1+$B$4) -> 2528.679 | C35: =B35*12 -> 30344.148 | D35: =D34*(1+$B$4) -> 30343.124 | E35: =C35-D35 -> 1.0240676 | F35: =F34*(1+$B$5)+E35 -> 355800.26 | G35: 72 | H35: =H34*(1+$B$4) -> 3676.431 | I35: =H35*12 -> 44117.173 | J35: =J34*(1+$B$4) -> 30343.124 | K35: =I35-J35 -> 13774.049 | L35: =(L34)*(1+$B$5)+K35 -> 142697.14 | M35: 72 | N35: =F35 -> 355800.26 | O35: =L35 -> 142697.14
A36: 73 | B36: =B35*(1+$B$4) -> 2591.896 | C36: =B36*12 -> 31102.752 | D36: =D35*(1+$B$4) -> 31101.702 | E36: =C36-D36 -> 1.0496693 | F36: =F35*(1+$B$5)+E36 -> 367400.4 | G36: 73 | H36: =H35*(1+$B$4) -> 3768.3418 | I36: =H36*12 -> 45220.102 | J36: =J35*(1+$B$4) -> 31101.702 | K36: =I36-J36 -> 14118.4 | L36: =(L35)*(1+$B$5)+K36 -> 161467.47 | M36: 73 | N36: =F36 -> 367400.4 | O36: =L36 -> 161467.47
A37: 74 | B37: =B36*(1+$B$4) -> 2656.6934 | C37: =B37*12 -> 31880.321 | D37: =D36*(1+$B$4) -> 31879.245 | E37: =C37-D37 -> 1.0759111 | F37: =F36*(1+$B$5)+E37 -> 379378.73 | G37: 74 | H37: =H36*(1+$B$4) -> 3862.5504 | I37: =H37*12 -> 46350.604 | J37: =J36*(1+$B$4) -> 31879.245 | K37: =I37-J37 -> 14471.36 | L37: =(L36)*(1+$B$5)+K37 -> 181202.67 | M37: 74 | N37: =F37 -> 379378.73 | O37: =L37 -> 181202.67
A38: 75 | B38: =B37*(1+$B$4) -> 2723.1107 | C38: =B38*12 -> 32677.329 | D38: =D37*(1+$B$4) -> 32676.226 | E38: =C38-D38 -> 1.1028088 | F38: =F37*(1+$B$5)+E38 -> 391747.58 | G38: 75 | H38: =H37*(1+$B$4) -> 3959.1141 | I38: =H38*12 -> 47509.37 | J38: =J37*(1+$B$4) -> 32676.226 | K38: =I38-J38 -> 14833.144 | L38: =(L37)*(1+$B$5)+K38 -> 201943.02 | M38: 75 | N38: =F38 -> 391747.58 | O38: =L38 -> 201943.02
A39: 76 | B39: =B38*(1+$B$4) -> 2791.1885 | C39: =B39*12 -> 33494.262 | D39: =D38*(1+$B$4) -> 33493.131 | E39: =C39-D39 -> 1.1303791 | F39: =F38*(1+$B$5)+E39 -> 404519.68 | G39: 76 | H39: =H38*(1+$B$4) -> 4058.092 | I39: =H39*12 -> 48697.104 | J39: =J38*(1+$B$4) -> 33493.131 | K39: =I39-J39 -> 15203.972 | L39: =(L38)*(1+$B$5)+K39 -> 223730.33 | M39: 76 | N39: =F39 -> 404519.68 | O39: =L39 -> 223730.33
A40: 77 | B40: =B39*(1+$B$4) -> 2860.9682 | C40: =B40*12 -> 34331.618 | D40: =D39*(1+$B$4) -> 34330.46 | E40: =C40-D40 -> 1.1586385 | F40: =F39*(1+$B$5)+E40 -> 417708.18 | G40: 77 | H40: =H39*(1+$B$4) -> 4159.5443 | I40: =H40*12 -> 49914.531 | J40: =J39*(1+$B$4) -> 34330.46 | K40: =I40-J40 -> 15584.072 | L40: =(L39)*(1+$B$5)+K40 -> 246608.01 | M40: 77 | N40: =F40 -> 417708.18 | O40: =L40 -> 246608.01
A41: 78 | B41: =B40*(1+$B$4) -> 2932.4924 | C41: =B41*12 -> 35189.909 | D41: =D40*(1+$B$4) -> 35188.721 | E41: =C41-D41 -> 1.1876045 | F41: =F40*(1+$B$5)+E41 -> 431326.65 | G41: 78 | H41: =H40*(1+$B$4) -> 4263.5329 | I41: =H41*12 -> 51162.395 | J41: =J40*(1+$B$4) -> 35188.721 | K41: =I41-J41 -> 15973.673 | L41: =(L40)*(1+$B$5)+K41 -> 270621.11 | M41: 78 | N41: =F41 -> 431326.65 | O41: =L41 -> 270621.11
A42: 79 | B42: =B41*(1+$B$4) -> 3005.8047 | C42: =B42*12 -> 36069.657 | D42: =D41*(1+$B$4) -> 36068.439 | E42: =C42-D42 -> 1.2172946 | F42: =F41*(1+$B$5)+E42 -> 445389.12 | G42: 79 | H42: =H41*(1+$B$4) -> 4370.1212 | I42: =H42*12 -> 52441.455 | J42: =J41*(1+$B$4) -> 36068.439 | K42: =I42-J42 -> 16373.015 | L42: =(L41)*(1+$B$5)+K42 -> 295816.37 | M42: 79 | N42: =F42 -> 445389.12 | O42: =L42 -> 295816.37
A43: 80 | B43: =B42*(1+$B$4) -> 3080.9498 | C43: =B43*12 -> 36971.398 | D43: =D42*(1+$B$4) -> 36970.15 | E43: =C43-D43 -> 1.247727 | F43: =F42*(1+$B$5)+E43 -> 459910.05 | G43: 80 | H43: =H42*(1+$B$4) -> 4479.3742 | I43: =H43*12 -> 53752.491 | J43: =J42*(1+$B$4) -> 36970.15 | K43: =I43-J43 -> 16782.341 | L43: =(L42)*(1+$B$5)+K43 -> 322242.33 | M43: 80 | N43: =F43 -> 459910.05 | O43: =L43 -> 322242.33
A44: 81 | B44: =B43*(1+$B$4) -> 3157.9736 | C44: =B44*12 -> 37895.683 | D44: =D43*(1+$B$4) -> 37894.404 | E44: =C44-D44 -> 1.2789201 | F44: =F43*(1+$B$5)+E44 -> 474904.4 | G44: 81 | H44: =H43*(1+$B$4) -> 4591.3586 | I44: =H44*12 -> 55096.303 | J44: =J43*(1+$B$4) -> 37894.404 | K44: =I44-J44 -> 17201.899 | L44: =(L43)*(1+$B$5)+K44 -> 349949.33 | M44: 81 | N44: =F44 -> 474904.4 | O44: =L44 -> 349949.33
...

Sheet RMD Tables 2025
B4: Table III | G4: Discount Rate | H4: =Main!B6 -> 0.025
B5: (Uniform Lifetime) | G5: Balance at 72 | H5: 2000000
B6: (For Use by: | G6: Cola | H6: =Main!B5 -> 0.025
B7: Unmarried Owners,
B8: Married Owners Whose Spouses Aren't More Than 10 Years Younger, and
B9: Married Owners Whose Spouses Aren't the Sole Beneficiaries of Their IRAs)
B11: Age | C11: Distribution Period | D11: Age | E11: Distribution Period | H11: Balance at 72 | J11: RMD | K11: Cola Adjusted Initial RMD | M11: Balance/RMD %
B12: 72 | C12: 27.4 | D12: 97 | E12: 7.8 | G12: 72 | H12: =H5 -> 2000000 | I12: =C12 -> 27.4 | J12: =H12/I12 -> 72992.701 | M12: =J12/H12 -> 0.03649635
B13: 73 | C13: 26.5 | D13: 98 | E13: 7.3 | G13: 73 | H13: =(H12-J12)*(1+$H$4) -> 1975182.5 | I13: =C13 -> 26.5 | J13: =H13/I13 -> 74535.188 | K13: =J12*(1+$H$6) -> 74817.518 | M13: =J13/H13 -> 0.037735849
B14: 74 | C14: 25.5 | D14: 99 | E14: 6.8 | G14: 74 | H14: =(H13-J13)*(1+$H$4) -> 1948163.5 | I14: =C14 -> 25.5 | J14: =H14/I14 -> 76398.568 | K14: =K13*(1+$H$6) -> 76687.956 | M14: =J14/H14 -> 0.039215686
B15: 75 | C15: 24.6 | D15: 100 | E15: 6.4 | G15: 75 | H15: =(H14-J14)*(1+$H$4) -> 1918559 | I15: =C15 -> 24.6 | J15: =H15/I15 -> 77990.205 | K15: =K14*(1+$H$6) -> 78605.155 | M15: =J15/H15 -> 0.040650407
B16: 76 | C16: 23.7 | D16: 101 | E16: 6 | G16: 76 | H16: =(H15-J15)*(1+$H$4) -> 1886583 | I16: =C16 -> 23.7 | J16: =H16/I16 -> 79602.66 | K16: =K15*(1+$H$6) -> 80570.284 | M16: =J16/H16 -> 0.042194093
B17: 77 | C17: 22.9 | D17: 102 | E17: 5.6 | G17: 77 | H17: =(H16-J16)*(1+$H$4) -> 1852154.9 | I17: =C17 -> 22.9 | J17: =H17/I17 -> 80880.126 | K17: =K16*(1+$H$6) -> 82584.541 | M17: =J17/H17 -> 0.043668122
B18: 78 | C18: 22 | D18: 103 | E18: 5.2 | G18: 78 | H18: =(H17-J17)*(1+$H$4) -> 1815556.6 | I18: =C18 -> 22 | J18: =H18/I18 -> 82525.302 | K18: =K17*(1+$H$6) -> 84649.155 | M18: =J18/H18 -> 0.045454545
B19: 79 | C19: 21.1 | D19: 104 | E19: 4.9 | G19: 79 | H19: =(H18-J18)*(1+$H$4) -> 1776357.1 | I19: =C19 -> 21.1 | J19: =H19/I19 -> 84187.541 | K19: =K18*(1+$H$6) -> 86765.383 | M19: =J19/H19 -> 0.047393365
B20: 80 | C20: 20.2 | D20: 105 | E20: 4.6 | G20: 80 | H20: =(H19-J19)*(1+$H$4) -> 1734473.8 | I20: =C20 -> 20.2 | J20: =H20/I20 -> 85865.041 | K20: =K19*(1+$H$6) -> 88934.518 | M20: =J20/H20 -> 0.04950495
B21: 81 | C21: 19.4 | D21: 106 | E21: 4.3 | G21: 81 | H21: =(H20-J20)*(1+$H$4) -> 1689824 | I21: =C21 -> 19.4 | J21: =H21/I21 -> 87104.33 | K21: =K20*(1+$H$6) -> 91157.881 | M21: =J21/H21 -> 0.051546392
B22: 82 | C22: 18.5 | D22: 107 | E22: 4.1 | G22: 82 | H22: =(H21-J21)*(1+$H$4) -> 1642787.7 | I22: =C22 -> 18.5 | J22: =H22/I22 -> 88799.333 | K22: =K21*(1+$H$6) -> 93436.828 | M22: =J22/H22 -> 0.054054054
B23: 83 | C23: 17.7 | D23: 108 | E23: 3.9 | G23: 83 | H23: =(H22-J22)*(1+$H$4) -> 1592838 | I23: =C23 -> 17.7 | J23: =H23/I23 -> 89990.849 | K23: =K22*(1+$H$6) -> 95772.749 | M23: =J23/H23 -> 0.056497175
B24: 84 | C24: 16.8 | D24: 109 | E24: 3.7 | G24: 84 | H24: =(H23-J23)*(1+$H$4) -> 1540418.4 | I24: =C24 -> 16.8 | J24: =H24/I24 -> 91691.569 | K24: =K23*(1+$H$6) -> 98167.067 | M24: =J24/H24 -> 0.05952381
B25: 85 | C25: 16 | D25: 110 | E25: 3.5 | G25: 85 | H25: =(H24-J24)*(1+$H$4) -> 1484945 | I25: =C25 -> 16 | J25: =H25/I25 -> 92809.06 | K25: =K24*(1+$H$6) -> 100621.24 | M25: =J25/H25 -> 0.0625
... B34: 94 | C34: 9.5 | D34: 119 | E34: 2.3 | G34: 94 | H34: =(H33-J33)*(1+$H$4) -> 885718.84 | I34: =C34 -> 9.5 | J34: =H34/I34 -> 93233.562 | K34: =K33*(1+$H$6) -> 125662.15 | M34: =J34/H34 -> 0.10526316
B35: 95 | C35: 8.9 | D35: 120 and over | E35: 2 | G35: 95 | H35: =(H34-J34)*(1+$H$4) -> 812297.41 | I35: =C35 -> 8.9 | J35: =H35/I35 -> 91269.371 | K35: =K34*(1+$H$6) -> 128803.7 | M35: =J35/H35 -> 0.11235955
B36: 96 | C36: 8.4 | G36: 96 | H36: =(H35-J35)*(1+$H$4) -> 739053.74 | I36: =C36 -> 8.4 | J36: =H36/I36 -> 87982.588 | K36: =K35*(1+$H$6) -> 132023.79 | M36: =J36/H36 -> 0.11904762
B37: 97 | G37: 97 | H37: =(H36-J36)*(1+$H$4) -> 667347.93 | I37: =E12 -> 7.8 | J37: =H37/I37 -> 85557.426 | K37: =K36*(1+$H$6) -> 135324.39 | M37: =J37/H37 -> 0.12820513
B38: 98 | G38: 98 | H38: =(H37-J37)*(1+$H$4) -> 596335.26 | I38: =E13 -> 7.3 | J38: =H38/I38 -> 81689.762 | K38: =K37*(1+$H$6) -> 138707.5 | M38: =J38/H38 -> 0.1369863
B39: 99 | G39: 99 | H39: =(H38-J38)*(1+$H$4) -> 527511.64 | I39: =E14 -> 6.8 | J39: =H39/I39 -> 77575.241 | K39: =K38*(1+$H$6) -> 142175.18 | M39: =J39/H39 -> 0.14705882
B40: 100 | G40: 100 | H40: =(H39-J39)*(1+$H$4) -> 461184.81 | I40: =E15 -> 6.4 | J40: =H40/I40 -> 72060.126 | K40: =K39*(1+$H$6) -> 145729.56 | M40: =J40/H40 -> 0.15625
B41: 101 | G41: 101 | H41: =(H40-J40)*(1+$H$4) -> 398852.8 | I41: =E16 -> 6 | J41: =H41/I41 -> 66475.466 | K41: =K40*(1+$H$6) -> 149372.8 | M41: =J41/H41 -> 0.16666667
B42: 102 | G42: 102 | H42: =(H41-J41)*(1+$H$4) -> 340686.76 | I42: =E17 -> 5.6 | J42: =H42/I42 -> 60836.922 | K42: =K41*(1+$H$6) -> 153107.12 | M42: =J42/H42 -> 0.17857143
B43: 103 | G43: 103 | H43: =(H42-J42)*(1+$H$4) -> 286846.09 | I43: =E18 -> 5.2 | J43: =H43/I43 -> 55162.709 | K43: =K42*(1+$H$6) -> 156934.8 | M43: =J43/H43 -> 0.19230769
B44: 104 | G44: 104 | H44: =(H43-J43)*(1+$H$4) -> 237475.46 | I44: =E19 -> 4.9 | J44: =H44/I44 -> 48464.38 | K44: =K43*(1+$H$6) -> 160858.17 | M44: =J44/H44 -> 0.20408163
B45: 105 | G45: 105 | H45: =(H44-J44)*(1+$H$4) -> 193736.36 | I45: =E20 -> 4.6 | J45: =H45/I45 -> 42116.6 | K45: =K44*(1+$H$6) -> 164879.62 | M45: =J45/H45 -> 0.2173913
B46: 106 | G46: 106 | H46: =(H45-J45)*(1+$H$4) -> 155410.25 | I46: =E21 -> 4.3 | J46: =H46/I46 -> 36141.92 | K46: =K45*(1+$H$6) -> 169001.62 | M46: =J46/H46 -> 0.23255814
B47: 107 | G47: 107 | H47: =(H46-J46)*(1+$H$4) -> 122250.04 | I47: =E22 -> 4.1 | J47: =H47/I47 -> 29817.084 | K47: =K46*(1+$H$6) -> 173226.66 | M47: =J47/H47 -> 0.24390244
B48: 108 | G48: 108 | H48: =(H47-J47)*(1+$H$4) -> 94743.783 | I48: =E23 -> 3.9 | J48: =H48/I48 -> 24293.278 | K48: =K47*(1+$H$6) -> 177557.32 | M48: =J48/H48 -> 0.25641026
... B60: 120 | G60: 120 | H60: =(H59-J59)*(1+$H$4) -> 986.82255 | I60: =E35 -> 2 | J60: =H60/I60 -> 493.41128 | K60: =K59*(1+$H$6) -> 238794.86 | M60: =J60/H60 -> 0.5

Sheet Cpi_index_inflation_montly_1925
A1: Series ID | B1: Year | C1: Period | D1: Label | E1: Value | F1: 12-Month % Change
A2: CUUR0000SA0 | B2: 1925 | C2: M01 | D2: 9133 | E2: 17.3 | F2: 0
A3: CUUR0000SA0 | B3: 1925 | C3: M02 | D3: 9164 | E3: 17.2 | F3: 0
A4: CUUR0000SA0 | B4: 1925 | C4: M03 | D4: 9192 | E4: 17.3 | F4: 1.2
A5: CUUR0000SA0 | B5: 1925 | C5: M04 | D5: 9223 | E5: 17.2 | F5: 1.2
A6: CUUR0000SA0 | B6: 1925 | C6: M05 | D6: 9253 | E6: 17.3 | F6: 1.8
A7: CUUR0000SA0 | B7: 1925 | C7: M06 | D7: 9284 | E7: 17.5 | F7: 2.9
A8: CUUR0000SA0 | B8: 1925 | C8: M07 | D8: 9314 | E8: 17.7 | F8: 3.5
A9: CUUR0000SA0 | B9: 1925 | C9: M08 | D9: 9345 | E9: 17.7 | F9: 4.1
A10: CUUR0000SA0 | B10: 1925 | C10: M09 | D10: 9376 | E10: 17.7 | F10: 3.5
A11: CUUR0000SA0 | B11: 1925 | C11: M10 | D11: 9406 | E11: 17.7 | F11: 2.9
A12: CUUR0000SA0 | B12: 1925 | C12: M11 | D12: 9437 | E12: 18 | F12: 4.7
A13: CUUR0000SA0 | B13: 1925 | C13: M12 | D13: 9467 | E13: 17.9 | F13: 3.5
... A1009: CUUR0000SA0 | B1009: 2008 | C1009: M12 | D1009: 39783 | E1009: 210.228 | F1009: 0.1
A1010: CUUR0000SA0 | B1010: 2009 | C1010: M01 | D1010: 39814 | E1010: 211.143
A1011: CUUR0000SA0 | B1011: 2009 | C1011: M02 | D1011: 39845 | E1011: 212.193
A1012: CUUR0000SA0 | B1012: 2009 | C1012: M03 | D1012: 39873 | E1012: 212.709
A1013: CUUR0000SA0 | B1013: 2009 | C1013: M04 | D1013: 39904 | E1013: 213.24
A1014: CUUR0000SA0 | B1014: 2009 | C1014: M05 | D1014: 39934 | E1014: 213.856
A1015: CUUR0000SA0 | B1015: 2009 | C1015: M06 | D1015: 39965 | E1015: 215.693
A1016: CUUR0000SA0 | B1016: 2009 | C1016: M07 | D1016: 39995 | E1016: 215.351
A1017: CUUR0000SA0 | B1017: 2009 | C1017: M08 | D1017: 40026 | E1017: 215.834
A1018: CUUR0000SA0 | B1018: 2009 | C1018: M09 | D1018: 40057 | E1018: 215.969
A1019: CUUR0000SA0 | B1019: 2009 | C1019: M10 | D1019: 40087 | E1019: 216.177
A1020: CUUR0000SA0 | B1020: 2009 | C1020: M11 | D1020: 40118 | E1020: 216.33
A1021: CUUR0000SA0 | B1021: 2009 | C1021: M12 | D1021: 40148 | E1021: 215.949
A1022: CUUR0000SA0 | B1022: 2010 | C1022: M01 | D1022: 40179 | E1022: 216.687 | F1022: 2.6
A1023: CUUR0000SA0 | B1023: 2010 | C1023: M02 | D1023: 40210 | E1023: 216.741 | F1023: 2.1
A1024: CUUR0000SA0 | B1024: 2010 | C1024: M03 | D1024: 40238 | E1024: 217.631 | F1024: 2.3
A1025: CUUR0000SA0 | B1025: 2010 | C1025: M04 | D1025: 40269 | E1025: 218.009 | F1025: 2.2
A1026: CUUR0000SA0 | B1026: 2010 | C1026: M05 | D1026: 40299 | E1026: 218.178 | F1026: 2
A1027: CUUR0000SA0 | B1027: 2010 | C1027: M06 | D1027: 40330 | E1027: 217.965 | F1027: 1.1
A1028: CUUR0000SA0 | B1028: 2010 | C1028: M07 | D1028: 40360 | E1028: 218.011 | F1028: 1.2
A1029: CUUR0000SA0 | B1029: 2010 | C1029: M08 | D1029: 40391 | E1029: 218.312 | F1029: 1.1
A1030: CUUR0000SA0 | B1030: 2010 | C1030: M09 | D1030: 40422 | E1030: 218.439 | F1030: 1.1
A1031: CUUR0000SA0 | B1031: 2010 | C1031: M10 | D1031: 40452 | E1031: 218.711 | F1031: 1.2
A1032: CUUR0000SA0 | B1032: 2010 | C1032: M11 | D1032: 40483 | E1032: 218.803 | F1032: 1.1
A1033: CUUR0000SA0 | B1033: 2010 | C1033: M12 | D1033: 40513 | E1033: 219.179 | F1033: 1.5
A1034: CUUR0000SA0 | B1034: 2011 | C1034: M01 | D1034: 40544 | E1034: 220.223
A1035: CUUR0000SA0 | B1035: 2011 | C1035: M02 | D1035: 40575 | E1035: 221.309
...

Sheet Inflation
C4: Table of Historical Inflation Rates in Percent
C5: (1914-2025)
C7: Year | D7: Jan | E7: Feb | F7: Mar | G7: Apr | H7: May | I7: Jun | J7: Jul | K7: Aug | L7: Sep | M7: Oct | N7: Nov | O7: Dec | P7: Ave
C8: 1914 | D8: 2 | E8: 1 | F8: 1 | G8: 0 | H8: 2.1 | I8: 1 | J8: 1 | K8: 3 | L8: 2 | M8: 1 | N8: 1 | O8: 1 | P8: 1
C9: 1915 | D9: 1 | E9: 1 | F9: 0 | G9: 2 | H9: 2 | I9: 2 | J9: 1 | K9: -1 | L9: -1 | M9: 1 | N9: 1 | O9: 2 | P9: 1
C10: 1916 | D10: 3 | E10: 4 | F10: 6.1 | G10: 6 | H10: 5.9 | I10: 6.9 | J10: 6.9 | K10: 7.9 | L10: 9.9 | M10: 10.8 | N10: 11.7 | O10: 12.6 | P10: 7.9
C11: 1917 | D11: 12.5 | E11: 15.4 | F11: 14.3 | G11: 18.9 | H11: 19.6 | I11: 20.4 | J11: 18.5 | K11: 19.3 | L11: 19.8 | M11: 19.5 | N11: 17.4 | O11: 18.1 | P11: 17.4
C12: 1918 | D12: 19.7 | E12: 17.5 | F12: 16.7 | G12: 12.7 | H12: 13.3 | I12: 13.1 | J12: 18 | K12: 18.5 | L12: 18 | M12: 18.5 | N12: 20.7 | O12: 20.4 | P12: 18
C13: 1919 | D13: 17.9 | E13: 14.9 | F13: 17.1 | G13: 17.6 | H13: 16.6 | I13: 15 | J13: 15.2 | K13: 14.9 | L13: 13.4 | M13: 13.1 | N13: 13.5 | O13: 14.5 | P13: 14.6
C14: 1920 | D14: 17 | E14: 20.4 | F14: 20.1 | G14: 21.6 | H14: 21.9 | I14: 23.7 | J14: 19.5 | K14: 14.7 | L14: 12.4 | M14: 9.9 | N14: 7 | O14: 2.6 | P14: 15.6
C15: 1921 | D15: -1.6 | E15: -5.6 | F15: -7.1 | G15: -10.8 | H15: -14.1 | I15: -15.8 | J15: -14.9 | K15: -12.8 | L15: -12.5 | M15: -12.1 | N15: -12.1 | O15: -10.8 | P15: -10.5
C16: 1922 | D16: -11.1 | E16: -8.2 | F16: -8.7 | G16: -7.7 | H16: -5.6 | I16: -5.1 | J16: -5.1 | K16: -6.2 | L16: -5.1 | M16: -4.6 | N16: -3.4 | O16: -2.3 | P16: -6.1
C17: 1923 | D17: -0.6 | E17: -0.6 | F17: 0.6 | G17: 1.2 | H17: 1.2 | I17: 1.8 | J17: 2.4 | K17: 3 | L17: 3.6 | M17: 3.6 | N17: 3 | O17: 2.4 | P17: 1.8
C18: 1924 | D18: 3 | E18: 2.4 | F18: 1.8 | G18: 0.6 | H18: 0.6 | I18: 0 | J18: -0.6 | K18: -0.6 | L18: -0.6 | M18: -0.6 | N18: -0.6 | O18: 0 | P18: 0
C19: 1925 | D19: 0 | E19: 0 | F19: 1.2 | G19: 1.2 | H19: 1.8 | I19: 2.9 | J19: 3.5 | K19: 4.1 | L19: 3.5 | M19: 2.9 | N19: 4.7 | O19: 3.5 | P19: 2.3
... C118: 2024 | D118: 3.1 | E118: 3.2 | F118: 3.5 | G118: 3.4 | H118: 3.3 | I118: 3 | J118: 2.9 | K118: 2.5 | L118: 2.4 | M118: 2.6 | N118: 2.7 | O118: 2.9 | P118: 2.9
C119: 2025 | D119: 3 | E119: 2.8 | F119: 2.4 | G119: 2.3 | H119: 2.4 | I119: 2.7 | J119: 2.7 | K119: 2.9 | L119: 3 | M119: – (*) | N119: 2.7 | O119: Avail.
O120: Jan.
O121: 13
P123: =(SUM(P8:P118)/111)/100 -> 0.03263964

Sheet Sheet1
B3: todays $1000
B5: future amout | C5: years | D5: discount rate | E5: PV
B6: 1000 | C6: 5 | D6: 0.0326 | E6: =PV(D6,C6,B6,B6) -> -5397.7098
C9: =B6/(1+D6)^C6 -> 851.80345

Sheet Sheet2

Sheet index test
A1: CPI
B3: Base year | C3: Test Year | D3: Factor | E3: base price | H3: Equivalent cost
B4: =Cpi_index_inflation_montly_1925!E1154 -> 261.582 | C4: =Cpi_index_inflation_montly_1925!E1166 -> 281.148 | D4: =B4/C4 -> 0.93040676 | E4: 1000 | F4: =E4*D4 -> 930.40676 | H4: =C4/B4 -> 1.0747987 | I4: =E4*H4 -> 1074.7987

Sheet Salarys 2024
C2: State | D2: Average Salary | E2: Median Salary | F2: color
C3: Alabama | D3: 53400 | E3: 41350 | F3: R
C4: Alaska | D4: 69880 | E4: 56140 | F4: R
C5: Arizona | D5: 63040 | E5: 47680 | F5: R
C6: Arkansas | D6: 51250 | E6: 39060 | F6: R
C7: California | D7: 76960 | E7: 54030 | F7: B
C8: Colorado | D8: 71960 | E8: 54050 | F8: B
C9: Connecticut | D9: 73740 | E9: 56130 | F9: B
C10: Delaware | D10: 65990 | E10: 49280 | F10: B
C11: Florida | D11: 60210 | E11: 45070 | F11: R
C12: Georgia | D12: 61250 | E12: 45480 | F12: R
C13: Hawaii | D13: 65030 | E13: 50510 | F13: B
C14: Idaho | D14: 55640 | E14: 44240 | F14: R
... C20: Louisiana | D20: 53440 | E20: 41320 | F20: R
C21: Maine | D21: 60000 | E21: 47590
C22: Maryland | D22: 73620 | E22: 55810
C23: Massachusetts | D23: 80330 | E23: 60690
C24: Michigan | D24: 60600 | E24: 46940 | F24: R
C25: Minnesota | D25: 66700 | E25: 50880
C26: Mississippi | D26: 47570 | E26: 37500 | F26: R
C27: Missouri | D27: 57580 | E27: 45080 | F27: R
C28: Montana | D28: 55920 | E28: 45690 | F28: R
C29: Nebraska | D29: 58080 | E29: 46440 | F29: R
C30: Nevada | D30: 58900 | E30: 44810 | F30: R
C31: New Hampshire | D31: 66110 | E31: 49980
C32: New Jersey | D32: 73980 | E32: 54860
C33: New Mexico | D33: 57520 | E33: 43620
C34: New York | D34: 78620 | E34: 56840
C35: North Carolina | D35: 59730 | E35: 45440 | F35: R
C36: North Dakota | D36: 59050 | E36: 48830 | F36: R
C37: Ohio | D37: 59890 | E37: 46690 | F37: R
C38: Oklahoma | D38: 53450 | E38: 41480 | F38: R
C39: Oregon | D39: 66710 | E39: 50010
C40: Pennsylvania | D40: 61920 | E40: 47430 | F40: R
C41: Rhode Island | D41: 66610 | E41: 50970
C42: South Carolina | D42: 54250 | E42: 42220 | F42: R
C43: South Dakota | D43: 53230 | E43: 43680 | F43: R
C44: Tennessee | D44: 56030 | E44: 43820 | F44: R
C45: Texas | D45: 61240 | E45: 45970 | F45: R
C46: Utah | D46: 61070 | E46: 47020 | F46: R
...

Sheet s&p_returns
B1: Year | C1: Return in %
B2: Column1 | C2: Column2
B3: 2024 | C3: 25.02
B4: 2023 | C4: 26.29
B5: 2022 | C5: -18.11
B6: 2021 | C6: 28.71
B7: 2020 | C7: 18.4
B8: 2019 | C8: 31.49
B9: 2018 | C9: -4.38
B10: 2017 | C10: 21.83
B11: 2016 | C11: 11.96
B12: 2015 | C12: 1.38
B13: 2014 | C13: 13.69
B14: 2013 | C14: 32.39
... B101: 1926 | C101: 11.62

Sheet SSI cola for the year
B3: Social Security Cost-Of-Living Adjustments
B4: Year | C4: COLA
B5: 1975 | C5: 8 | E5: Average | F5: =SUM(C5:C55)/((B55-B5)+1) -> 3.7294118
B6: 1976 | C6: 6.4
B7: 1977 | C7: 5.9
B8: 1978 | C8: 6.5
B9: 1979 | C9: 9.9
B10: 1980 | C10: 14.3
B11: 1981 | C11: 11.2
B12: 1982 | C12: 7.4
B13: 1983 | C13: 3.5
B14: 1984 | C14: 3.5
B15: 1985 | C15: 3.1
B16: 1986 | C16: 1.3
B17: 1987 | C17: 4.2
... B28: 1998 | C28: 1.3
B29: 1999 a | C29: 2.5
B30: 2000 | C30: 3.5
B31: 2001 | C31: 2.6
B32: 2002 | C32: 1.4
B33: 2003 | C33: 2.1
B34: 2004 | C34: 2.7
B35: 2005 | C35: 4.1
B36: 2006 | C36: 3.3
B37: 2007 | C37: 2.3
B38: 2008 | C38: 5.8
B39: 2009 | C39: 0
B40: 2010 | C40: 0
B41: 2011 | C41: 3.6
... B55: 2025 | C55: 2.8
